2024-10-04 10:39:43,251 INFO [app:126] Tentativa de login do usuário: luis
2024-10-04 10:39:43,619 INFO [app:173] Usuário luis logado com sucesso.
2024-10-04 10:39:43,642 INFO [app:92] Usuário 10 carregado com sucesso.
2024-10-04 10:40:03,489 INFO [app:92] Usuário 10 carregado com sucesso.
2024-10-04 10:40:37,481 INFO [app:92] Usuário 10 carregado com sucesso.
2024-10-04 10:40:51,185 INFO [app:92] Usuário 10 carregado com sucesso.
2024-10-04 10:40:51,185 INFO [app:188] Usuário 10 fez logout.
2024-10-04 10:41:12,272 INFO [app:126] Tentativa de login do usuário: luis
2024-10-04 10:41:12,687 INFO [app:173] Usuário luis logado com sucesso.
2024-10-04 10:41:12,710 INFO [app:92] Usuário 10 carregado com sucesso.
2024-10-04 10:41:21,139 INFO [app:92] Usuário 10 carregado com sucesso.
2024-10-04 10:41:23,255 INFO [app:92] Usuário 10 carregado com sucesso.
2024-10-04 10:41:24,503 INFO [app:92] Usuário 10 carregado com sucesso.
2024-10-04 10:41:25,799 INFO [app:92] Usuário 10 carregado com sucesso.
2024-10-04 10:41:27,240 INFO [app:92] Usuário 10 carregado com sucesso.
2024-10-04 10:41:29,160 INFO [app:92] Usuário 10 carregado com sucesso.
2024-10-04 10:41:40,634 INFO [app:92] Usuário 10 carregado com sucesso.
2024-10-04 10:51:24,194 INFO [wasyncore:485] Serving on http://0.0.0.0:8279
2024-10-04 10:51:31,970 INFO [app:92] Usuário 10 carregado com sucesso.
2024-10-04 10:51:35,359 INFO [app:92] Usuário 10 carregado com sucesso.
2024-10-04 10:51:35,360 INFO [app:188] Usuário 10 fez logout.
2024-10-04 10:51:39,167 INFO [app:126] Tentativa de login do usuário: luis
2024-10-04 10:51:39,597 INFO [app:173] Usuário luis logado com sucesso.
2024-10-04 10:51:39,629 INFO [app:92] Usuário 10 carregado com sucesso.
2024-10-04 10:51:49,780 INFO [app:92] Usuário 10 carregado com sucesso.
2024-10-04 10:52:02,058 INFO [app:92] Usuário 10 carregado com sucesso.
2024-10-04 10:52:44,294 INFO [wasyncore:485] Serving on http://0.0.0.0:8279
2024-10-04 10:52:45,181 INFO [app:92] Usuário 10 carregado com sucesso.
2024-10-04 10:52:50,459 INFO [app:92] Usuário 10 carregado com sucesso.
2024-10-04 10:52:51,174 INFO [app:92] Usuário 10 carregado com sucesso.
2024-10-04 10:52:51,621 INFO [app:92] Usuário 10 carregado com sucesso.
2024-10-04 10:52:52,103 INFO [app:92] Usuário 10 carregado com sucesso.
2024-10-04 10:52:52,477 INFO [app:92] Usuário 10 carregado com sucesso.
2024-10-04 10:52:52,833 INFO [app:92] Usuário 10 carregado com sucesso.
2024-10-04 10:52:53,191 INFO [app:92] Usuário 10 carregado com sucesso.
2024-10-04 10:52:53,589 INFO [app:92] Usuário 10 carregado com sucesso.
2024-10-04 10:53:12,819 ERROR [app:363] Server Error: Traceback (most recent call last):
  File "C:\Users\luis.vieira\AppData\Local\Programs\Python\Python312\Lib\site-packages\flask\app.py", line 880, in full_dispatch_request
    rv = self.dispatch_request()
         ^^^^^^^^^^^^^^^^^^^^^^^
  File "C:\Users\luis.vieira\AppData\Local\Programs\Python\Python312\Lib\site-packages\flask\app.py", line 865, in dispatch_request
    return self.ensure_sync(self.view_functions[rule.endpoint])(**view_args)  # type: ignore[no-any-return]
           ^^^^^^^^^^^^^^^^^^^^^^^^^^^^^^^^^^^^^^^^^^^^^^^^^^^^^^^^^^^^^^^^^
  File "C:\Users\luis.vieira\Documents\GitHub\Flask4\app.py", line 358, in force_error
    return nao_existe()
           ^^^^^^^^^^
NameError: name 'nao_existe' is not defined

2024-10-04 10:53:12,838 INFO [app:92] Usuário 10 carregado com sucesso.
2024-10-04 10:53:16,398 INFO [app:92] Usuário 10 carregado com sucesso.
2024-10-04 10:54:19,426 INFO [wasyncore:485] Serving on http://0.0.0.0:8279
2024-10-04 10:54:21,097 INFO [app:92] Usuário 10 carregado com sucesso.
2024-10-04 10:54:21,143 ERROR [app:363] Server Error: Traceback (most recent call last):
  File "C:\Users\luis.vieira\AppData\Local\Programs\Python\Python312\Lib\site-packages\flask\app.py", line 880, in full_dispatch_request
    rv = self.dispatch_request()
         ^^^^^^^^^^^^^^^^^^^^^^^
  File "C:\Users\luis.vieira\AppData\Local\Programs\Python\Python312\Lib\site-packages\flask\app.py", line 865, in dispatch_request
    return self.ensure_sync(self.view_functions[rule.endpoint])(**view_args)  # type: ignore[no-any-return]
           ^^^^^^^^^^^^^^^^^^^^^^^^^^^^^^^^^^^^^^^^^^^^^^^^^^^^^^^^^^^^^^^^^
  File "C:\Users\luis.vieira\AppData\Local\Programs\Python\Python312\Lib\site-packages\flask_login\utils.py", line 290, in decorated_view
    return current_app.ensure_sync(func)(*args, **kwargs)
           ^^^^^^^^^^^^^^^^^^^^^^^^^^^^^^^^^^^^^^^^^^^^^^
  File "C:\Users\luis.vieira\Documents\GitHub\Flask4\app.py", line 313, in view_logs
    return render_template('logs.html', log_content=log_content)
           ^^^^^^^^^^^^^^^^^^^^^^^^^^^^^^^^^^^^^^^^^^^^^^^^^^^^^
  File "C:\Users\luis.vieira\AppData\Local\Programs\Python\Python312\Lib\site-packages\flask\templating.py", line 150, in render_template
    return _render(app, template, context)
           ^^^^^^^^^^^^^^^^^^^^^^^^^^^^^^^
  File "C:\Users\luis.vieira\AppData\Local\Programs\Python\Python312\Lib\site-packages\flask\templating.py", line 131, in _render
    rv = template.render(context)
         ^^^^^^^^^^^^^^^^^^^^^^^^
  File "C:\Users\luis.vieira\AppData\Local\Programs\Python\Python312\Lib\site-packages\jinja2\environment.py", line 1304, in render
    self.environment.handle_exception()
  File "C:\Users\luis.vieira\AppData\Local\Programs\Python\Python312\Lib\site-packages\jinja2\environment.py", line 939, in handle_exception
    raise rewrite_traceback_stack(source=source)
  File "C:\Users\luis.vieira\Documents\GitHub\Flask4\templates\logs.html", line 22, in top-level template code
    {{ form.hidden_tag() }} <!-- Proteção CSRF -->
    ^^^^^^^^^^^^^^^^^^^^^^^^^
  File "C:\Users\luis.vieira\AppData\Local\Programs\Python\Python312\Lib\site-packages\jinja2\environment.py", line 487, in getattr
    return getattr(obj, attribute)
           ^^^^^^^^^^^^^^^^^^^^^^^
jinja2.exceptions.UndefinedError: 'form' is undefined

2024-10-04 10:54:25,098 INFO [app:92] Usuário 10 carregado com sucesso.
2024-10-04 10:54:25,117 ERROR [app:363] Server Error: Traceback (most recent call last):
  File "C:\Users\luis.vieira\AppData\Local\Programs\Python\Python312\Lib\site-packages\flask\app.py", line 880, in full_dispatch_request
    rv = self.dispatch_request()
         ^^^^^^^^^^^^^^^^^^^^^^^
  File "C:\Users\luis.vieira\AppData\Local\Programs\Python\Python312\Lib\site-packages\flask\app.py", line 865, in dispatch_request
    return self.ensure_sync(self.view_functions[rule.endpoint])(**view_args)  # type: ignore[no-any-return]
           ^^^^^^^^^^^^^^^^^^^^^^^^^^^^^^^^^^^^^^^^^^^^^^^^^^^^^^^^^^^^^^^^^
  File "C:\Users\luis.vieira\AppData\Local\Programs\Python\Python312\Lib\site-packages\flask_login\utils.py", line 290, in decorated_view
    return current_app.ensure_sync(func)(*args, **kwargs)
           ^^^^^^^^^^^^^^^^^^^^^^^^^^^^^^^^^^^^^^^^^^^^^^
  File "C:\Users\luis.vieira\Documents\GitHub\Flask4\app.py", line 313, in view_logs
    return render_template('logs.html', log_content=log_content)
           ^^^^^^^^^^^^^^^^^^^^^^^^^^^^^^^^^^^^^^^^^^^^^^^^^^^^^
  File "C:\Users\luis.vieira\AppData\Local\Programs\Python\Python312\Lib\site-packages\flask\templating.py", line 150, in render_template
    return _render(app, template, context)
           ^^^^^^^^^^^^^^^^^^^^^^^^^^^^^^^
  File "C:\Users\luis.vieira\AppData\Local\Programs\Python\Python312\Lib\site-packages\flask\templating.py", line 131, in _render
    rv = template.render(context)
         ^^^^^^^^^^^^^^^^^^^^^^^^
  File "C:\Users\luis.vieira\AppData\Local\Programs\Python\Python312\Lib\site-packages\jinja2\environment.py", line 1304, in render
    self.environment.handle_exception()
  File "C:\Users\luis.vieira\AppData\Local\Programs\Python\Python312\Lib\site-packages\jinja2\environment.py", line 939, in handle_exception
    raise rewrite_traceback_stack(source=source)
  File "C:\Users\luis.vieira\Documents\GitHub\Flask4\templates\logs.html", line 22, in top-level template code
    {{ form.hidden_tag() }} <!-- Proteção CSRF -->
    ^^^^^^^^^^^^^^^^^^^^^^^^^
  File "C:\Users\luis.vieira\AppData\Local\Programs\Python\Python312\Lib\site-packages\jinja2\environment.py", line 487, in getattr
    return getattr(obj, attribute)
           ^^^^^^^^^^^^^^^^^^^^^^^
jinja2.exceptions.UndefinedError: 'form' is undefined

2024-10-04 10:55:08,085 INFO [wasyncore:485] Serving on http://0.0.0.0:8279
2024-10-04 10:55:09,031 INFO [app:92] Usuário 10 carregado com sucesso.
2024-10-04 10:55:09,075 ERROR [app:363] Server Error: Traceback (most recent call last):
  File "C:\Users\luis.vieira\AppData\Local\Programs\Python\Python312\Lib\site-packages\flask\app.py", line 880, in full_dispatch_request
    rv = self.dispatch_request()
         ^^^^^^^^^^^^^^^^^^^^^^^
  File "C:\Users\luis.vieira\AppData\Local\Programs\Python\Python312\Lib\site-packages\flask\app.py", line 865, in dispatch_request
    return self.ensure_sync(self.view_functions[rule.endpoint])(**view_args)  # type: ignore[no-any-return]
           ^^^^^^^^^^^^^^^^^^^^^^^^^^^^^^^^^^^^^^^^^^^^^^^^^^^^^^^^^^^^^^^^^
  File "C:\Users\luis.vieira\AppData\Local\Programs\Python\Python312\Lib\site-packages\flask_login\utils.py", line 290, in decorated_view
    return current_app.ensure_sync(func)(*args, **kwargs)
           ^^^^^^^^^^^^^^^^^^^^^^^^^^^^^^^^^^^^^^^^^^^^^^
  File "C:\Users\luis.vieira\Documents\GitHub\Flask4\app.py", line 313, in view_logs
    return render_template('logs.html', log_content=log_content)
           ^^^^^^^^^^^^^^^^^^^^^^^^^^^^^^^^^^^^^^^^^^^^^^^^^^^^^
  File "C:\Users\luis.vieira\AppData\Local\Programs\Python\Python312\Lib\site-packages\flask\templating.py", line 150, in render_template
    return _render(app, template, context)
           ^^^^^^^^^^^^^^^^^^^^^^^^^^^^^^^
  File "C:\Users\luis.vieira\AppData\Local\Programs\Python\Python312\Lib\site-packages\flask\templating.py", line 131, in _render
    rv = template.render(context)
         ^^^^^^^^^^^^^^^^^^^^^^^^
  File "C:\Users\luis.vieira\AppData\Local\Programs\Python\Python312\Lib\site-packages\jinja2\environment.py", line 1304, in render
    self.environment.handle_exception()
  File "C:\Users\luis.vieira\AppData\Local\Programs\Python\Python312\Lib\site-packages\jinja2\environment.py", line 939, in handle_exception
    raise rewrite_traceback_stack(source=source)
  File "C:\Users\luis.vieira\Documents\GitHub\Flask4\templates\logs.html", line 22, in top-level template code
    {{ form.hidden_tag() }} <!-- Proteção CSRF -->
    ^^^^^^^^^^^^^^^^^^^^^^^^^
  File "C:\Users\luis.vieira\AppData\Local\Programs\Python\Python312\Lib\site-packages\jinja2\environment.py", line 487, in getattr
    return getattr(obj, attribute)
           ^^^^^^^^^^^^^^^^^^^^^^^
jinja2.exceptions.UndefinedError: 'form' is undefined

2024-10-04 10:56:21,432 INFO [wasyncore:485] Serving on http://0.0.0.0:8279
2024-10-04 10:56:22,789 INFO [app:92] Usuário 10 carregado com sucesso.
2024-10-04 10:56:22,830 ERROR [app:363] Server Error: Traceback (most recent call last):
  File "C:\Users\luis.vieira\AppData\Local\Programs\Python\Python312\Lib\site-packages\flask\app.py", line 880, in full_dispatch_request
    rv = self.dispatch_request()
         ^^^^^^^^^^^^^^^^^^^^^^^
  File "C:\Users\luis.vieira\AppData\Local\Programs\Python\Python312\Lib\site-packages\flask\app.py", line 865, in dispatch_request
    return self.ensure_sync(self.view_functions[rule.endpoint])(**view_args)  # type: ignore[no-any-return]
           ^^^^^^^^^^^^^^^^^^^^^^^^^^^^^^^^^^^^^^^^^^^^^^^^^^^^^^^^^^^^^^^^^
  File "C:\Users\luis.vieira\AppData\Local\Programs\Python\Python312\Lib\site-packages\flask_login\utils.py", line 290, in decorated_view
    return current_app.ensure_sync(func)(*args, **kwargs)
           ^^^^^^^^^^^^^^^^^^^^^^^^^^^^^^^^^^^^^^^^^^^^^^
  File "C:\Users\luis.vieira\Documents\GitHub\Flask4\app.py", line 313, in view_logs
    return render_template('logs.html', log_content=log_content)
           ^^^^^^^^^^^^^^^^^^^^^^^^^^^^^^^^^^^^^^^^^^^^^^^^^^^^^
  File "C:\Users\luis.vieira\AppData\Local\Programs\Python\Python312\Lib\site-packages\flask\templating.py", line 150, in render_template
    return _render(app, template, context)
           ^^^^^^^^^^^^^^^^^^^^^^^^^^^^^^^
  File "C:\Users\luis.vieira\AppData\Local\Programs\Python\Python312\Lib\site-packages\flask\templating.py", line 131, in _render
    rv = template.render(context)
         ^^^^^^^^^^^^^^^^^^^^^^^^
  File "C:\Users\luis.vieira\AppData\Local\Programs\Python\Python312\Lib\site-packages\jinja2\environment.py", line 1304, in render
    self.environment.handle_exception()
  File "C:\Users\luis.vieira\AppData\Local\Programs\Python\Python312\Lib\site-packages\jinja2\environment.py", line 939, in handle_exception
    raise rewrite_traceback_stack(source=source)
  File "C:\Users\luis.vieira\Documents\GitHub\Flask4\templates\logs.html", line 27, in top-level template code
    {{ form.hidden_tag() }} <!-- Proteção CSRF -->
    ^^^^^^^^^^^^^^^^^^^^^^^^^
  File "C:\Users\luis.vieira\AppData\Local\Programs\Python\Python312\Lib\site-packages\jinja2\environment.py", line 487, in getattr
    return getattr(obj, attribute)
           ^^^^^^^^^^^^^^^^^^^^^^^
jinja2.exceptions.UndefinedError: 'form' is undefined

2024-10-04 10:57:08,487 INFO [wasyncore:485] Serving on http://0.0.0.0:8279
2024-10-04 10:57:13,047 INFO [app:92] Usuário 10 carregado com sucesso.
2024-10-04 10:57:13,090 ERROR [app:363] Server Error: Traceback (most recent call last):
  File "C:\Users\luis.vieira\AppData\Local\Programs\Python\Python312\Lib\site-packages\flask\app.py", line 880, in full_dispatch_request
    rv = self.dispatch_request()
         ^^^^^^^^^^^^^^^^^^^^^^^
  File "C:\Users\luis.vieira\AppData\Local\Programs\Python\Python312\Lib\site-packages\flask\app.py", line 865, in dispatch_request
    return self.ensure_sync(self.view_functions[rule.endpoint])(**view_args)  # type: ignore[no-any-return]
           ^^^^^^^^^^^^^^^^^^^^^^^^^^^^^^^^^^^^^^^^^^^^^^^^^^^^^^^^^^^^^^^^^
  File "C:\Users\luis.vieira\AppData\Local\Programs\Python\Python312\Lib\site-packages\flask_login\utils.py", line 290, in decorated_view
    return current_app.ensure_sync(func)(*args, **kwargs)
           ^^^^^^^^^^^^^^^^^^^^^^^^^^^^^^^^^^^^^^^^^^^^^^
  File "C:\Users\luis.vieira\Documents\GitHub\Flask4\app.py", line 313, in view_logs
    return render_template('logs.html', log_content=log_content)
           ^^^^^^^^^^^^^^^^^^^^^^^^^^^^^^^^^^^^^^^^^^^^^^^^^^^^^
  File "C:\Users\luis.vieira\AppData\Local\Programs\Python\Python312\Lib\site-packages\flask\templating.py", line 150, in render_template
    return _render(app, template, context)
           ^^^^^^^^^^^^^^^^^^^^^^^^^^^^^^^
  File "C:\Users\luis.vieira\AppData\Local\Programs\Python\Python312\Lib\site-packages\flask\templating.py", line 131, in _render
    rv = template.render(context)
         ^^^^^^^^^^^^^^^^^^^^^^^^
  File "C:\Users\luis.vieira\AppData\Local\Programs\Python\Python312\Lib\site-packages\jinja2\environment.py", line 1304, in render
    self.environment.handle_exception()
  File "C:\Users\luis.vieira\AppData\Local\Programs\Python\Python312\Lib\site-packages\jinja2\environment.py", line 939, in handle_exception
    raise rewrite_traceback_stack(source=source)
  File "C:\Users\luis.vieira\Documents\GitHub\Flask4\templates\logs.html", line 28, in top-level template code
    {{ form.hidden_tag() }} <!-- Proteção CSRF -->
    ^^^^^^^^^^^^^^^^^^^^^^^^^
  File "C:\Users\luis.vieira\AppData\Local\Programs\Python\Python312\Lib\site-packages\jinja2\environment.py", line 487, in getattr
    return getattr(obj, attribute)
           ^^^^^^^^^^^^^^^^^^^^^^^
jinja2.exceptions.UndefinedError: 'form' is undefined

2024-10-04 10:57:15,554 INFO [app:92] Usuário 10 carregado com sucesso.
2024-10-04 10:57:20,735 INFO [app:92] Usuário 10 carregado com sucesso.
2024-10-04 10:57:20,764 ERROR [app:363] Server Error: Traceback (most recent call last):
  File "C:\Users\luis.vieira\AppData\Local\Programs\Python\Python312\Lib\site-packages\flask\app.py", line 880, in full_dispatch_request
    rv = self.dispatch_request()
         ^^^^^^^^^^^^^^^^^^^^^^^
  File "C:\Users\luis.vieira\AppData\Local\Programs\Python\Python312\Lib\site-packages\flask\app.py", line 865, in dispatch_request
    return self.ensure_sync(self.view_functions[rule.endpoint])(**view_args)  # type: ignore[no-any-return]
           ^^^^^^^^^^^^^^^^^^^^^^^^^^^^^^^^^^^^^^^^^^^^^^^^^^^^^^^^^^^^^^^^^
  File "C:\Users\luis.vieira\AppData\Local\Programs\Python\Python312\Lib\site-packages\flask_login\utils.py", line 290, in decorated_view
    return current_app.ensure_sync(func)(*args, **kwargs)
           ^^^^^^^^^^^^^^^^^^^^^^^^^^^^^^^^^^^^^^^^^^^^^^
  File "C:\Users\luis.vieira\Documents\GitHub\Flask4\app.py", line 313, in view_logs
    return render_template('logs.html', log_content=log_content)
           ^^^^^^^^^^^^^^^^^^^^^^^^^^^^^^^^^^^^^^^^^^^^^^^^^^^^^
  File "C:\Users\luis.vieira\AppData\Local\Programs\Python\Python312\Lib\site-packages\flask\templating.py", line 150, in render_template
    return _render(app, template, context)
           ^^^^^^^^^^^^^^^^^^^^^^^^^^^^^^^
  File "C:\Users\luis.vieira\AppData\Local\Programs\Python\Python312\Lib\site-packages\flask\templating.py", line 131, in _render
    rv = template.render(context)
         ^^^^^^^^^^^^^^^^^^^^^^^^
  File "C:\Users\luis.vieira\AppData\Local\Programs\Python\Python312\Lib\site-packages\jinja2\environment.py", line 1304, in render
    self.environment.handle_exception()
  File "C:\Users\luis.vieira\AppData\Local\Programs\Python\Python312\Lib\site-packages\jinja2\environment.py", line 939, in handle_exception
    raise rewrite_traceback_stack(source=source)
  File "C:\Users\luis.vieira\Documents\GitHub\Flask4\templates\logs.html", line 28, in top-level template code
    {{ form.hidden_tag() }} <!-- Proteção CSRF -->
    ^^^^^^^^^^^^^^^^^^^^^^^^^
  File "C:\Users\luis.vieira\AppData\Local\Programs\Python\Python312\Lib\site-packages\jinja2\environment.py", line 487, in getattr
    return getattr(obj, attribute)
           ^^^^^^^^^^^^^^^^^^^^^^^
jinja2.exceptions.UndefinedError: 'form' is undefined

2024-10-04 10:58:25,214 INFO [wasyncore:485] Serving on http://0.0.0.0:8279
2024-10-04 10:58:26,420 INFO [app:92] Usuário 10 carregado com sucesso.
2024-10-04 10:58:26,459 ERROR [app:363] Server Error: Traceback (most recent call last):
  File "C:\Users\luis.vieira\AppData\Local\Programs\Python\Python312\Lib\site-packages\flask\app.py", line 880, in full_dispatch_request
    rv = self.dispatch_request()
         ^^^^^^^^^^^^^^^^^^^^^^^
  File "C:\Users\luis.vieira\AppData\Local\Programs\Python\Python312\Lib\site-packages\flask\app.py", line 865, in dispatch_request
    return self.ensure_sync(self.view_functions[rule.endpoint])(**view_args)  # type: ignore[no-any-return]
           ^^^^^^^^^^^^^^^^^^^^^^^^^^^^^^^^^^^^^^^^^^^^^^^^^^^^^^^^^^^^^^^^^
  File "C:\Users\luis.vieira\AppData\Local\Programs\Python\Python312\Lib\site-packages\flask_login\utils.py", line 290, in decorated_view
    return current_app.ensure_sync(func)(*args, **kwargs)
           ^^^^^^^^^^^^^^^^^^^^^^^^^^^^^^^^^^^^^^^^^^^^^^
  File "C:\Users\luis.vieira\Documents\GitHub\Flask4\app.py", line 313, in view_logs
    return render_template('logs.html', log_content=log_content)
           ^^^^^^^^^^^^^^^^^^^^^^^^^^^^^^^^^^^^^^^^^^^^^^^^^^^^^
  File "C:\Users\luis.vieira\AppData\Local\Programs\Python\Python312\Lib\site-packages\flask\templating.py", line 150, in render_template
    return _render(app, template, context)
           ^^^^^^^^^^^^^^^^^^^^^^^^^^^^^^^
  File "C:\Users\luis.vieira\AppData\Local\Programs\Python\Python312\Lib\site-packages\flask\templating.py", line 131, in _render
    rv = template.render(context)
         ^^^^^^^^^^^^^^^^^^^^^^^^
  File "C:\Users\luis.vieira\AppData\Local\Programs\Python\Python312\Lib\site-packages\jinja2\environment.py", line 1304, in render
    self.environment.handle_exception()
  File "C:\Users\luis.vieira\AppData\Local\Programs\Python\Python312\Lib\site-packages\jinja2\environment.py", line 939, in handle_exception
    raise rewrite_traceback_stack(source=source)
  File "C:\Users\luis.vieira\Documents\GitHub\Flask4\templates\logs.html", line 27, in top-level template code
    {{ form.hidden_tag() }} <!-- Proteção CSRF -->
    ^^^^^^^^^^^^^^^^^^^^^^^^^
  File "C:\Users\luis.vieira\AppData\Local\Programs\Python\Python312\Lib\site-packages\jinja2\environment.py", line 487, in getattr
    return getattr(obj, attribute)
           ^^^^^^^^^^^^^^^^^^^^^^^
jinja2.exceptions.UndefinedError: 'form' is undefined

2024-10-04 10:59:30,985 INFO [wasyncore:485] Serving on http://0.0.0.0:8279
2024-10-04 10:59:32,188 INFO [app:92] Usuário 10 carregado com sucesso.
2024-10-04 10:59:32,241 ERROR [app:363] Server Error: Traceback (most recent call last):
  File "C:\Users\luis.vieira\AppData\Local\Programs\Python\Python312\Lib\site-packages\flask\app.py", line 880, in full_dispatch_request
    rv = self.dispatch_request()
         ^^^^^^^^^^^^^^^^^^^^^^^
  File "C:\Users\luis.vieira\AppData\Local\Programs\Python\Python312\Lib\site-packages\flask\app.py", line 865, in dispatch_request
    return self.ensure_sync(self.view_functions[rule.endpoint])(**view_args)  # type: ignore[no-any-return]
           ^^^^^^^^^^^^^^^^^^^^^^^^^^^^^^^^^^^^^^^^^^^^^^^^^^^^^^^^^^^^^^^^^
  File "C:\Users\luis.vieira\AppData\Local\Programs\Python\Python312\Lib\site-packages\flask_login\utils.py", line 290, in decorated_view
    return current_app.ensure_sync(func)(*args, **kwargs)
           ^^^^^^^^^^^^^^^^^^^^^^^^^^^^^^^^^^^^^^^^^^^^^^
  File "C:\Users\luis.vieira\Documents\GitHub\Flask4\app.py", line 313, in view_logs
    return render_template('logs.html', log_content=log_content)
           ^^^^^^^^^^^^^^^^^^^^^^^^^^^^^^^^^^^^^^^^^^^^^^^^^^^^^
  File "C:\Users\luis.vieira\AppData\Local\Programs\Python\Python312\Lib\site-packages\flask\templating.py", line 150, in render_template
    return _render(app, template, context)
           ^^^^^^^^^^^^^^^^^^^^^^^^^^^^^^^
  File "C:\Users\luis.vieira\AppData\Local\Programs\Python\Python312\Lib\site-packages\flask\templating.py", line 131, in _render
    rv = template.render(context)
         ^^^^^^^^^^^^^^^^^^^^^^^^
  File "C:\Users\luis.vieira\AppData\Local\Programs\Python\Python312\Lib\site-packages\jinja2\environment.py", line 1304, in render
    self.environment.handle_exception()
  File "C:\Users\luis.vieira\AppData\Local\Programs\Python\Python312\Lib\site-packages\jinja2\environment.py", line 939, in handle_exception
    raise rewrite_traceback_stack(source=source)
  File "C:\Users\luis.vieira\Documents\GitHub\Flask4\templates\logs.html", line 19, in top-level template code
    {{ form.hidden_tag() }} <!-- Proteção CSRF -->
    ^^^^^^^^^^^^^^^^^^^^^^^^^
  File "C:\Users\luis.vieira\AppData\Local\Programs\Python\Python312\Lib\site-packages\jinja2\environment.py", line 487, in getattr
    return getattr(obj, attribute)
           ^^^^^^^^^^^^^^^^^^^^^^^
jinja2.exceptions.UndefinedError: 'form' is undefined

2024-10-04 11:04:55,012 INFO [wasyncore:485] Serving on http://0.0.0.0:8279
2024-10-04 11:04:55,209 INFO [app:92] Usuário 10 carregado com sucesso.
2024-10-04 11:04:55,268 ERROR [app:363] Server Error: Traceback (most recent call last):
  File "C:\Users\luis.vieira\AppData\Local\Programs\Python\Python312\Lib\site-packages\flask\app.py", line 880, in full_dispatch_request
    rv = self.dispatch_request()
         ^^^^^^^^^^^^^^^^^^^^^^^
  File "C:\Users\luis.vieira\AppData\Local\Programs\Python\Python312\Lib\site-packages\flask\app.py", line 865, in dispatch_request
    return self.ensure_sync(self.view_functions[rule.endpoint])(**view_args)  # type: ignore[no-any-return]
           ^^^^^^^^^^^^^^^^^^^^^^^^^^^^^^^^^^^^^^^^^^^^^^^^^^^^^^^^^^^^^^^^^
  File "C:\Users\luis.vieira\AppData\Local\Programs\Python\Python312\Lib\site-packages\flask_login\utils.py", line 290, in decorated_view
    return current_app.ensure_sync(func)(*args, **kwargs)
           ^^^^^^^^^^^^^^^^^^^^^^^^^^^^^^^^^^^^^^^^^^^^^^
  File "C:\Users\luis.vieira\Documents\GitHub\Flask4\app.py", line 313, in view_logs
    return render_template('logs.html', log_content=log_content)
           ^^^^^^^^^^^^^^^^^^^^^^^^^^^^^^^^^^^^^^^^^^^^^^^^^^^^^
  File "C:\Users\luis.vieira\AppData\Local\Programs\Python\Python312\Lib\site-packages\flask\templating.py", line 150, in render_template
    return _render(app, template, context)
           ^^^^^^^^^^^^^^^^^^^^^^^^^^^^^^^
  File "C:\Users\luis.vieira\AppData\Local\Programs\Python\Python312\Lib\site-packages\flask\templating.py", line 131, in _render
    rv = template.render(context)
         ^^^^^^^^^^^^^^^^^^^^^^^^
  File "C:\Users\luis.vieira\AppData\Local\Programs\Python\Python312\Lib\site-packages\jinja2\environment.py", line 1304, in render
    self.environment.handle_exception()
  File "C:\Users\luis.vieira\AppData\Local\Programs\Python\Python312\Lib\site-packages\jinja2\environment.py", line 939, in handle_exception
    raise rewrite_traceback_stack(source=source)
  File "C:\Users\luis.vieira\Documents\GitHub\Flask4\templates\logs.html", line 12, in top-level template code
    {{ form.hidden_tag() }} <!-- Proteção CSRF -->
    ^^^^^^^^^^^^^^^^^^^^^^^^^
  File "C:\Users\luis.vieira\AppData\Local\Programs\Python\Python312\Lib\site-packages\jinja2\environment.py", line 487, in getattr
    return getattr(obj, attribute)
           ^^^^^^^^^^^^^^^^^^^^^^^
jinja2.exceptions.UndefinedError: 'form' is undefined

2024-10-04 11:05:01,745 INFO [app:92] Usuário 10 carregado com sucesso.
2024-10-04 11:06:22,523 INFO [wasyncore:485] Serving on http://0.0.0.0:8279
2024-10-04 11:06:26,075 INFO [app:92] Usuário 10 carregado com sucesso.
2024-10-04 11:06:26,117 ERROR [app:363] Server Error: Traceback (most recent call last):
  File "C:\Users\luis.vieira\AppData\Local\Programs\Python\Python312\Lib\site-packages\flask\app.py", line 880, in full_dispatch_request
    rv = self.dispatch_request()
         ^^^^^^^^^^^^^^^^^^^^^^^
  File "C:\Users\luis.vieira\AppData\Local\Programs\Python\Python312\Lib\site-packages\flask\app.py", line 865, in dispatch_request
    return self.ensure_sync(self.view_functions[rule.endpoint])(**view_args)  # type: ignore[no-any-return]
           ^^^^^^^^^^^^^^^^^^^^^^^^^^^^^^^^^^^^^^^^^^^^^^^^^^^^^^^^^^^^^^^^^
  File "C:\Users\luis.vieira\AppData\Local\Programs\Python\Python312\Lib\site-packages\flask_login\utils.py", line 290, in decorated_view
    return current_app.ensure_sync(func)(*args, **kwargs)
           ^^^^^^^^^^^^^^^^^^^^^^^^^^^^^^^^^^^^^^^^^^^^^^
  File "C:\Users\luis.vieira\Documents\GitHub\Flask4\app.py", line 313, in view_logs
    return render_template('logs.html', log_content=log_content)
           ^^^^^^^^^^^^^^^^^^^^^^^^^^^^^^^^^^^^^^^^^^^^^^^^^^^^^
  File "C:\Users\luis.vieira\AppData\Local\Programs\Python\Python312\Lib\site-packages\flask\templating.py", line 150, in render_template
    return _render(app, template, context)
           ^^^^^^^^^^^^^^^^^^^^^^^^^^^^^^^
  File "C:\Users\luis.vieira\AppData\Local\Programs\Python\Python312\Lib\site-packages\flask\templating.py", line 131, in _render
    rv = template.render(context)
         ^^^^^^^^^^^^^^^^^^^^^^^^
  File "C:\Users\luis.vieira\AppData\Local\Programs\Python\Python312\Lib\site-packages\jinja2\environment.py", line 1304, in render
    self.environment.handle_exception()
  File "C:\Users\luis.vieira\AppData\Local\Programs\Python\Python312\Lib\site-packages\jinja2\environment.py", line 939, in handle_exception
    raise rewrite_traceback_stack(source=source)
  File "C:\Users\luis.vieira\Documents\GitHub\Flask4\templates\logs.html", line 19, in top-level template code
    {{ form.hidden_tag() }} <!-- Proteção CSRF -->
    ^^^^^^^^^^^^^^^^^^^^^^^^^
  File "C:\Users\luis.vieira\AppData\Local\Programs\Python\Python312\Lib\site-packages\jinja2\environment.py", line 487, in getattr
    return getattr(obj, attribute)
           ^^^^^^^^^^^^^^^^^^^^^^^
jinja2.exceptions.UndefinedError: 'form' is undefined

2024-10-04 11:08:12,063 INFO [app:92] Usuário 10 carregado com sucesso.
2024-10-04 11:08:12,089 ERROR [app:363] Server Error: Traceback (most recent call last):
  File "C:\Users\luis.vieira\AppData\Local\Programs\Python\Python312\Lib\site-packages\flask\app.py", line 880, in full_dispatch_request
    rv = self.dispatch_request()
         ^^^^^^^^^^^^^^^^^^^^^^^
  File "C:\Users\luis.vieira\AppData\Local\Programs\Python\Python312\Lib\site-packages\flask\app.py", line 865, in dispatch_request
    return self.ensure_sync(self.view_functions[rule.endpoint])(**view_args)  # type: ignore[no-any-return]
           ^^^^^^^^^^^^^^^^^^^^^^^^^^^^^^^^^^^^^^^^^^^^^^^^^^^^^^^^^^^^^^^^^
  File "C:\Users\luis.vieira\AppData\Local\Programs\Python\Python312\Lib\site-packages\flask_login\utils.py", line 290, in decorated_view
    return current_app.ensure_sync(func)(*args, **kwargs)
           ^^^^^^^^^^^^^^^^^^^^^^^^^^^^^^^^^^^^^^^^^^^^^^
  File "C:\Users\luis.vieira\Documents\GitHub\Flask4\app.py", line 313, in view_logs
    return render_template('logs.html', log_content=log_content)
           ^^^^^^^^^^^^^^^^^^^^^^^^^^^^^^^^^^^^^^^^^^^^^^^^^^^^^
  File "C:\Users\luis.vieira\AppData\Local\Programs\Python\Python312\Lib\site-packages\flask\templating.py", line 150, in render_template
    return _render(app, template, context)
           ^^^^^^^^^^^^^^^^^^^^^^^^^^^^^^^
  File "C:\Users\luis.vieira\AppData\Local\Programs\Python\Python312\Lib\site-packages\flask\templating.py", line 131, in _render
    rv = template.render(context)
         ^^^^^^^^^^^^^^^^^^^^^^^^
  File "C:\Users\luis.vieira\AppData\Local\Programs\Python\Python312\Lib\site-packages\jinja2\environment.py", line 1304, in render
    self.environment.handle_exception()
  File "C:\Users\luis.vieira\AppData\Local\Programs\Python\Python312\Lib\site-packages\jinja2\environment.py", line 939, in handle_exception
    raise rewrite_traceback_stack(source=source)
  File "C:\Users\luis.vieira\Documents\GitHub\Flask4\templates\logs.html", line 19, in top-level template code
    <h1>Logs do Sistema</h1>
  File "C:\Users\luis.vieira\AppData\Local\Programs\Python\Python312\Lib\site-packages\jinja2\environment.py", line 487, in getattr
    return getattr(obj, attribute)
           ^^^^^^^^^^^^^^^^^^^^^^^
jinja2.exceptions.UndefinedError: 'form' is undefined

2024-10-04 11:10:57,365 INFO [app:92] Usuário 10 carregado com sucesso.
2024-10-04 11:10:57,393 ERROR [app:363] Server Error: Traceback (most recent call last):
  File "C:\Users\luis.vieira\AppData\Local\Programs\Python\Python312\Lib\site-packages\flask\app.py", line 880, in full_dispatch_request
    rv = self.dispatch_request()
         ^^^^^^^^^^^^^^^^^^^^^^^
  File "C:\Users\luis.vieira\AppData\Local\Programs\Python\Python312\Lib\site-packages\flask\app.py", line 865, in dispatch_request
    return self.ensure_sync(self.view_functions[rule.endpoint])(**view_args)  # type: ignore[no-any-return]
           ^^^^^^^^^^^^^^^^^^^^^^^^^^^^^^^^^^^^^^^^^^^^^^^^^^^^^^^^^^^^^^^^^
  File "C:\Users\luis.vieira\AppData\Local\Programs\Python\Python312\Lib\site-packages\flask_login\utils.py", line 290, in decorated_view
    return current_app.ensure_sync(func)(*args, **kwargs)
           ^^^^^^^^^^^^^^^^^^^^^^^^^^^^^^^^^^^^^^^^^^^^^^
  File "C:\Users\luis.vieira\Documents\GitHub\Flask4\app.py", line 313, in view_logs
    return render_template('logs.html', log_content=log_content)
           ^^^^^^^^^^^^^^^^^^^^^^^^^^^^^^^^^^^^^^^^^^^^^^^^^^^^^
  File "C:\Users\luis.vieira\AppData\Local\Programs\Python\Python312\Lib\site-packages\flask\templating.py", line 150, in render_template
    return _render(app, template, context)
           ^^^^^^^^^^^^^^^^^^^^^^^^^^^^^^^
  File "C:\Users\luis.vieira\AppData\Local\Programs\Python\Python312\Lib\site-packages\flask\templating.py", line 131, in _render
    rv = template.render(context)
         ^^^^^^^^^^^^^^^^^^^^^^^^
  File "C:\Users\luis.vieira\AppData\Local\Programs\Python\Python312\Lib\site-packages\jinja2\environment.py", line 1304, in render
    self.environment.handle_exception()
  File "C:\Users\luis.vieira\AppData\Local\Programs\Python\Python312\Lib\site-packages\jinja2\environment.py", line 939, in handle_exception
    raise rewrite_traceback_stack(source=source)
  File "C:\Users\luis.vieira\Documents\GitHub\Flask4\templates\logs.html", line 19, in top-level template code
    <h1>Logs do Sistema</h1>
  File "C:\Users\luis.vieira\AppData\Local\Programs\Python\Python312\Lib\site-packages\jinja2\environment.py", line 487, in getattr
    return getattr(obj, attribute)
           ^^^^^^^^^^^^^^^^^^^^^^^
jinja2.exceptions.UndefinedError: 'form' is undefined

2024-10-04 11:10:59,784 INFO [app:92] Usuário 10 carregado com sucesso.
2024-10-04 11:10:59,801 ERROR [app:363] Server Error: Traceback (most recent call last):
  File "C:\Users\luis.vieira\AppData\Local\Programs\Python\Python312\Lib\site-packages\flask\app.py", line 880, in full_dispatch_request
    rv = self.dispatch_request()
         ^^^^^^^^^^^^^^^^^^^^^^^
  File "C:\Users\luis.vieira\AppData\Local\Programs\Python\Python312\Lib\site-packages\flask\app.py", line 865, in dispatch_request
    return self.ensure_sync(self.view_functions[rule.endpoint])(**view_args)  # type: ignore[no-any-return]
           ^^^^^^^^^^^^^^^^^^^^^^^^^^^^^^^^^^^^^^^^^^^^^^^^^^^^^^^^^^^^^^^^^
  File "C:\Users\luis.vieira\AppData\Local\Programs\Python\Python312\Lib\site-packages\flask_login\utils.py", line 290, in decorated_view
    return current_app.ensure_sync(func)(*args, **kwargs)
           ^^^^^^^^^^^^^^^^^^^^^^^^^^^^^^^^^^^^^^^^^^^^^^
  File "C:\Users\luis.vieira\Documents\GitHub\Flask4\app.py", line 313, in view_logs
    return render_template('logs.html', log_content=log_content)
           ^^^^^^^^^^^^^^^^^^^^^^^^^^^^^^^^^^^^^^^^^^^^^^^^^^^^^
  File "C:\Users\luis.vieira\AppData\Local\Programs\Python\Python312\Lib\site-packages\flask\templating.py", line 150, in render_template
    return _render(app, template, context)
           ^^^^^^^^^^^^^^^^^^^^^^^^^^^^^^^
  File "C:\Users\luis.vieira\AppData\Local\Programs\Python\Python312\Lib\site-packages\flask\templating.py", line 131, in _render
    rv = template.render(context)
         ^^^^^^^^^^^^^^^^^^^^^^^^
  File "C:\Users\luis.vieira\AppData\Local\Programs\Python\Python312\Lib\site-packages\jinja2\environment.py", line 1304, in render
    self.environment.handle_exception()
  File "C:\Users\luis.vieira\AppData\Local\Programs\Python\Python312\Lib\site-packages\jinja2\environment.py", line 939, in handle_exception
    raise rewrite_traceback_stack(source=source)
  File "C:\Users\luis.vieira\Documents\GitHub\Flask4\templates\logs.html", line 19, in top-level template code
    <h1>Logs do Sistema</h1>
  File "C:\Users\luis.vieira\AppData\Local\Programs\Python\Python312\Lib\site-packages\jinja2\environment.py", line 487, in getattr
    return getattr(obj, attribute)
           ^^^^^^^^^^^^^^^^^^^^^^^
jinja2.exceptions.UndefinedError: 'form' is undefined

2024-10-04 11:10:59,842 WARNING [app:368] Página não encontrada: http://localhost:8279/favicon.ico
2024-10-04 11:10:59,858 INFO [app:92] Usuário 10 carregado com sucesso.
2024-10-04 11:11:03,685 INFO [app:92] Usuário 10 carregado com sucesso.
2024-10-04 11:11:06,228 INFO [app:92] Usuário 10 carregado com sucesso.
2024-10-04 11:11:06,229 INFO [app:188] Usuário 10 fez logout.
2024-10-04 11:11:12,009 INFO [app:126] Tentativa de login do usuário: jockey
2024-10-04 11:11:12,362 INFO [app:173] Usuário jockey logado com sucesso.
2024-10-04 11:11:12,384 INFO [app:92] Usuário 1 carregado com sucesso.
2024-10-04 11:11:16,673 INFO [app:92] Usuário 1 carregado com sucesso.
2024-10-04 11:11:16,673 WARNING [app:102] Acesso negado ao usuário 1. Tipo de usuário: 2
2024-10-04 11:11:16,704 INFO [app:92] Usuário 1 carregado com sucesso.
2024-10-04 11:13:56,318 INFO [app:92] Usuário 1 carregado com sucesso.
2024-10-04 11:13:56,319 WARNING [app:102] Acesso negado ao usuário 1. Tipo de usuário: 2
2024-10-04 11:13:56,344 INFO [app:92] Usuário 1 carregado com sucesso.
2024-10-04 11:14:04,324 INFO [app:92] Usuário 1 carregado com sucesso.
2024-10-04 11:14:04,324 INFO [app:188] Usuário 1 fez logout.
2024-10-04 11:14:18,340 INFO [app:126] Tentativa de login do usuário: luis
2024-10-04 11:14:18,707 INFO [app:173] Usuário luis logado com sucesso.
2024-10-04 11:14:18,746 INFO [app:92] Usuário 10 carregado com sucesso.
2024-10-04 11:14:22,922 INFO [app:92] Usuário 10 carregado com sucesso.
2024-10-04 11:14:29,023 INFO [app:92] Usuário 10 carregado com sucesso.
2024-10-04 11:14:29,039 ERROR [app:363] Server Error: Traceback (most recent call last):
  File "C:\Users\luis.vieira\AppData\Local\Programs\Python\Python312\Lib\site-packages\flask\app.py", line 880, in full_dispatch_request
    rv = self.dispatch_request()
         ^^^^^^^^^^^^^^^^^^^^^^^
  File "C:\Users\luis.vieira\AppData\Local\Programs\Python\Python312\Lib\site-packages\flask\app.py", line 865, in dispatch_request
    return self.ensure_sync(self.view_functions[rule.endpoint])(**view_args)  # type: ignore[no-any-return]
           ^^^^^^^^^^^^^^^^^^^^^^^^^^^^^^^^^^^^^^^^^^^^^^^^^^^^^^^^^^^^^^^^^
  File "C:\Users\luis.vieira\AppData\Local\Programs\Python\Python312\Lib\site-packages\flask_login\utils.py", line 290, in decorated_view
    return current_app.ensure_sync(func)(*args, **kwargs)
           ^^^^^^^^^^^^^^^^^^^^^^^^^^^^^^^^^^^^^^^^^^^^^^
  File "C:\Users\luis.vieira\Documents\GitHub\Flask4\app.py", line 313, in view_logs
    return render_template('logs.html', log_content=log_content)
           ^^^^^^^^^^^^^^^^^^^^^^^^^^^^^^^^^^^^^^^^^^^^^^^^^^^^^
  File "C:\Users\luis.vieira\AppData\Local\Programs\Python\Python312\Lib\site-packages\flask\templating.py", line 150, in render_template
    return _render(app, template, context)
           ^^^^^^^^^^^^^^^^^^^^^^^^^^^^^^^
  File "C:\Users\luis.vieira\AppData\Local\Programs\Python\Python312\Lib\site-packages\flask\templating.py", line 131, in _render
    rv = template.render(context)
         ^^^^^^^^^^^^^^^^^^^^^^^^
  File "C:\Users\luis.vieira\AppData\Local\Programs\Python\Python312\Lib\site-packages\jinja2\environment.py", line 1304, in render
    self.environment.handle_exception()
  File "C:\Users\luis.vieira\AppData\Local\Programs\Python\Python312\Lib\site-packages\jinja2\environment.py", line 939, in handle_exception
    raise rewrite_traceback_stack(source=source)
  File "C:\Users\luis.vieira\Documents\GitHub\Flask4\templates\logs.html", line 19, in top-level template code
    <h1>Logs do Sistema</h1>
  File "C:\Users\luis.vieira\AppData\Local\Programs\Python\Python312\Lib\site-packages\jinja2\environment.py", line 487, in getattr
    return getattr(obj, attribute)
           ^^^^^^^^^^^^^^^^^^^^^^^
jinja2.exceptions.UndefinedError: 'form' is undefined

2024-10-04 11:16:55,989 INFO [app:92] Usuário 10 carregado com sucesso.
2024-10-04 11:16:56,045 ERROR [app:363] Server Error: Traceback (most recent call last):
  File "C:\Users\luis.vieira\AppData\Local\Programs\Python\Python312\Lib\site-packages\flask\app.py", line 880, in full_dispatch_request
    rv = self.dispatch_request()
         ^^^^^^^^^^^^^^^^^^^^^^^
  File "C:\Users\luis.vieira\AppData\Local\Programs\Python\Python312\Lib\site-packages\flask\app.py", line 865, in dispatch_request
    return self.ensure_sync(self.view_functions[rule.endpoint])(**view_args)  # type: ignore[no-any-return]
           ^^^^^^^^^^^^^^^^^^^^^^^^^^^^^^^^^^^^^^^^^^^^^^^^^^^^^^^^^^^^^^^^^
  File "C:\Users\luis.vieira\AppData\Local\Programs\Python\Python312\Lib\site-packages\flask_login\utils.py", line 290, in decorated_view
    return current_app.ensure_sync(func)(*args, **kwargs)
           ^^^^^^^^^^^^^^^^^^^^^^^^^^^^^^^^^^^^^^^^^^^^^^
  File "C:\Users\luis.vieira\Documents\GitHub\Flask4\app.py", line 313, in view_logs
    form = DummyForm()
           ^^^^^^^^^^^^
  File "C:\Users\luis.vieira\AppData\Local\Programs\Python\Python312\Lib\site-packages\flask\templating.py", line 150, in render_template
    return _render(app, template, context)
           ^^^^^^^^^^^^^^^^^^^^^^^^^^^^^^^
  File "C:\Users\luis.vieira\AppData\Local\Programs\Python\Python312\Lib\site-packages\flask\templating.py", line 131, in _render
    rv = template.render(context)
         ^^^^^^^^^^^^^^^^^^^^^^^^
  File "C:\Users\luis.vieira\AppData\Local\Programs\Python\Python312\Lib\site-packages\jinja2\environment.py", line 1304, in render
    self.environment.handle_exception()
  File "C:\Users\luis.vieira\AppData\Local\Programs\Python\Python312\Lib\site-packages\jinja2\environment.py", line 939, in handle_exception
    raise rewrite_traceback_stack(source=source)
  File "C:\Users\luis.vieira\Documents\GitHub\Flask4\templates\logs.html", line 19, in top-level template code
    <h1>Logs do Sistema</h1>
  File "C:\Users\luis.vieira\AppData\Local\Programs\Python\Python312\Lib\site-packages\jinja2\environment.py", line 487, in getattr
    return getattr(obj, attribute)
           ^^^^^^^^^^^^^^^^^^^^^^^
jinja2.exceptions.UndefinedError: 'form' is undefined

2024-10-04 11:18:14,566 INFO [wasyncore:485] Serving on http://0.0.0.0:8279
2024-10-04 11:18:15,803 INFO [app:92] usuario 10 carregado com sucesso.
2024-10-04 11:25:31,486 INFO [app:92] usuario 10 carregado com sucesso.
2024-10-04 11:25:34,221 INFO [app:92] usuario 10 carregado com sucesso.
2024-10-04 11:25:35,005 INFO [app:92] usuario 10 carregado com sucesso.
2024-10-04 11:25:35,626 INFO [extension:1095] ratelimit 30 per 1 hour (127.0.0.1) exceeded at endpoint: view_logs
2024-10-04 11:25:35,660 ERROR [app:364] Server Error: Traceback (most recent call last):
  File "C:\Users\luis.vieira\AppData\Local\Programs\Python\Python312\Lib\site-packages\flask\app.py", line 878, in full_dispatch_request
    rv = self.preprocess_request()
         ^^^^^^^^^^^^^^^^^^^^^^^^^
  File "C:\Users\luis.vieira\AppData\Local\Programs\Python\Python312\Lib\site-packages\flask\app.py", line 1253, in preprocess_request
    rv = self.ensure_sync(before_func)()
         ^^^^^^^^^^^^^^^^^^^^^^^^^^^^^^^
  File "C:\Users\luis.vieira\AppData\Local\Programs\Python\Python312\Lib\site-packages\flask_limiter\extension.py", line 1160, in _check_request_limit
    raise e
  File "C:\Users\luis.vieira\AppData\Local\Programs\Python\Python312\Lib\site-packages\flask_limiter\extension.py", line 1157, in _check_request_limit
    self.__evaluate_limits(endpoint, all_limits)
  File "C:\Users\luis.vieira\AppData\Local\Programs\Python\Python312\Lib\site-packages\flask_limiter\extension.py", line 1141, in __evaluate_limits
    raise RateLimitExceeded(
flask_limiter.errors.RateLimitExceeded: 429 Too Many Requests: 30 per 1 hour

2024-10-04 11:25:35,680 INFO [app:92] usuario 10 carregado com sucesso.
2024-10-04 11:25:36,776 INFO [extension:1095] ratelimit 30 per 1 hour (127.0.0.1) exceeded at endpoint: view_logs
2024-10-04 11:25:36,778 ERROR [app:364] Server Error: Traceback (most recent call last):
  File "C:\Users\luis.vieira\AppData\Local\Programs\Python\Python312\Lib\site-packages\flask\app.py", line 878, in full_dispatch_request
    rv = self.preprocess_request()
         ^^^^^^^^^^^^^^^^^^^^^^^^^
  File "C:\Users\luis.vieira\AppData\Local\Programs\Python\Python312\Lib\site-packages\flask\app.py", line 1253, in preprocess_request
    rv = self.ensure_sync(before_func)()
         ^^^^^^^^^^^^^^^^^^^^^^^^^^^^^^^
  File "C:\Users\luis.vieira\AppData\Local\Programs\Python\Python312\Lib\site-packages\flask_limiter\extension.py", line 1160, in _check_request_limit
    raise e
  File "C:\Users\luis.vieira\AppData\Local\Programs\Python\Python312\Lib\site-packages\flask_limiter\extension.py", line 1157, in _check_request_limit
    self.__evaluate_limits(endpoint, all_limits)
  File "C:\Users\luis.vieira\AppData\Local\Programs\Python\Python312\Lib\site-packages\flask_limiter\extension.py", line 1141, in __evaluate_limits
    raise RateLimitExceeded(
flask_limiter.errors.RateLimitExceeded: 429 Too Many Requests: 30 per 1 hour

2024-10-04 11:25:36,793 INFO [app:92] usuario 10 carregado com sucesso.
2024-10-04 11:25:37,328 INFO [extension:1095] ratelimit 30 per 1 hour (127.0.0.1) exceeded at endpoint: view_logs
2024-10-04 11:25:37,329 ERROR [app:364] Server Error: Traceback (most recent call last):
  File "C:\Users\luis.vieira\AppData\Local\Programs\Python\Python312\Lib\site-packages\flask\app.py", line 878, in full_dispatch_request
    rv = self.preprocess_request()
         ^^^^^^^^^^^^^^^^^^^^^^^^^
  File "C:\Users\luis.vieira\AppData\Local\Programs\Python\Python312\Lib\site-packages\flask\app.py", line 1253, in preprocess_request
    rv = self.ensure_sync(before_func)()
         ^^^^^^^^^^^^^^^^^^^^^^^^^^^^^^^
  File "C:\Users\luis.vieira\AppData\Local\Programs\Python\Python312\Lib\site-packages\flask_limiter\extension.py", line 1160, in _check_request_limit
    raise e
  File "C:\Users\luis.vieira\AppData\Local\Programs\Python\Python312\Lib\site-packages\flask_limiter\extension.py", line 1157, in _check_request_limit
    self.__evaluate_limits(endpoint, all_limits)
  File "C:\Users\luis.vieira\AppData\Local\Programs\Python\Python312\Lib\site-packages\flask_limiter\extension.py", line 1141, in __evaluate_limits
    raise RateLimitExceeded(
flask_limiter.errors.RateLimitExceeded: 429 Too Many Requests: 30 per 1 hour

2024-10-04 11:25:37,347 INFO [app:92] usuario 10 carregado com sucesso.
2024-10-04 11:25:37,821 INFO [extension:1095] ratelimit 30 per 1 hour (127.0.0.1) exceeded at endpoint: view_logs
2024-10-04 11:25:37,822 ERROR [app:364] Server Error: Traceback (most recent call last):
  File "C:\Users\luis.vieira\AppData\Local\Programs\Python\Python312\Lib\site-packages\flask\app.py", line 878, in full_dispatch_request
    rv = self.preprocess_request()
         ^^^^^^^^^^^^^^^^^^^^^^^^^
  File "C:\Users\luis.vieira\AppData\Local\Programs\Python\Python312\Lib\site-packages\flask\app.py", line 1253, in preprocess_request
    rv = self.ensure_sync(before_func)()
         ^^^^^^^^^^^^^^^^^^^^^^^^^^^^^^^
  File "C:\Users\luis.vieira\AppData\Local\Programs\Python\Python312\Lib\site-packages\flask_limiter\extension.py", line 1160, in _check_request_limit
    raise e
  File "C:\Users\luis.vieira\AppData\Local\Programs\Python\Python312\Lib\site-packages\flask_limiter\extension.py", line 1157, in _check_request_limit
    self.__evaluate_limits(endpoint, all_limits)
  File "C:\Users\luis.vieira\AppData\Local\Programs\Python\Python312\Lib\site-packages\flask_limiter\extension.py", line 1141, in __evaluate_limits
    raise RateLimitExceeded(
flask_limiter.errors.RateLimitExceeded: 429 Too Many Requests: 30 per 1 hour

2024-10-04 11:25:37,837 INFO [app:92] usuario 10 carregado com sucesso.
2024-10-04 11:25:52,251 INFO [extension:1095] ratelimit 30 per 1 hour (127.0.0.1) exceeded at endpoint: view_logs
2024-10-04 11:25:52,252 ERROR [app:364] Server Error: Traceback (most recent call last):
  File "C:\Users\luis.vieira\AppData\Local\Programs\Python\Python312\Lib\site-packages\flask\app.py", line 878, in full_dispatch_request
    rv = self.preprocess_request()
         ^^^^^^^^^^^^^^^^^^^^^^^^^
  File "C:\Users\luis.vieira\AppData\Local\Programs\Python\Python312\Lib\site-packages\flask\app.py", line 1253, in preprocess_request
    rv = self.ensure_sync(before_func)()
         ^^^^^^^^^^^^^^^^^^^^^^^^^^^^^^^
  File "C:\Users\luis.vieira\AppData\Local\Programs\Python\Python312\Lib\site-packages\flask_limiter\extension.py", line 1160, in _check_request_limit
    raise e
  File "C:\Users\luis.vieira\AppData\Local\Programs\Python\Python312\Lib\site-packages\flask_limiter\extension.py", line 1157, in _check_request_limit
    self.__evaluate_limits(endpoint, all_limits)
  File "C:\Users\luis.vieira\AppData\Local\Programs\Python\Python312\Lib\site-packages\flask_limiter\extension.py", line 1141, in __evaluate_limits
    raise RateLimitExceeded(
flask_limiter.errors.RateLimitExceeded: 429 Too Many Requests: 30 per 1 hour

2024-10-04 11:25:52,267 INFO [app:92] usuario 10 carregado com sucesso.
2024-10-04 11:26:11,768 INFO [extension:1095] ratelimit 30 per 1 hour (127.0.0.1) exceeded at endpoint: view_logs
2024-10-04 11:26:11,770 ERROR [app:364] Server Error: Traceback (most recent call last):
  File "C:\Users\luis.vieira\AppData\Local\Programs\Python\Python312\Lib\site-packages\flask\app.py", line 878, in full_dispatch_request
    rv = self.preprocess_request()
         ^^^^^^^^^^^^^^^^^^^^^^^^^
  File "C:\Users\luis.vieira\AppData\Local\Programs\Python\Python312\Lib\site-packages\flask\app.py", line 1253, in preprocess_request
    rv = self.ensure_sync(before_func)()
         ^^^^^^^^^^^^^^^^^^^^^^^^^^^^^^^
  File "C:\Users\luis.vieira\AppData\Local\Programs\Python\Python312\Lib\site-packages\flask_limiter\extension.py", line 1160, in _check_request_limit
    raise e
  File "C:\Users\luis.vieira\AppData\Local\Programs\Python\Python312\Lib\site-packages\flask_limiter\extension.py", line 1157, in _check_request_limit
    self.__evaluate_limits(endpoint, all_limits)
  File "C:\Users\luis.vieira\AppData\Local\Programs\Python\Python312\Lib\site-packages\flask_limiter\extension.py", line 1141, in __evaluate_limits
    raise RateLimitExceeded(
flask_limiter.errors.RateLimitExceeded: 429 Too Many Requests: 30 per 1 hour

2024-10-04 11:26:11,790 INFO [app:92] usuario 10 carregado com sucesso.
2024-10-04 11:26:15,575 INFO [app:92] usuario 10 carregado com sucesso.
2024-10-04 11:26:19,098 INFO [app:92] usuario 10 carregado com sucesso.
2024-10-04 11:26:33,792 INFO [app:92] usuario 10 carregado com sucesso.
2024-10-04 11:26:33,792 INFO [app:188] usuario 10 fez logout.
2024-10-04 11:26:37,803 INFO [app:126] Tentativa de login do usuario: jockey
2024-10-04 11:26:38,139 INFO [app:173] usuario jockey logado com sucesso.
2024-10-04 11:26:38,163 INFO [app:92] usuario 1 carregado com sucesso.
2024-10-04 11:26:44,969 INFO [extension:1095] ratelimit 30 per 1 hour (127.0.0.1) exceeded at endpoint: view_logs
2024-10-04 11:26:44,972 ERROR [app:364] Server Error: Traceback (most recent call last):
  File "C:\Users\luis.vieira\AppData\Local\Programs\Python\Python312\Lib\site-packages\flask\app.py", line 878, in full_dispatch_request
    rv = self.preprocess_request()
         ^^^^^^^^^^^^^^^^^^^^^^^^^
  File "C:\Users\luis.vieira\AppData\Local\Programs\Python\Python312\Lib\site-packages\flask\app.py", line 1253, in preprocess_request
    rv = self.ensure_sync(before_func)()
         ^^^^^^^^^^^^^^^^^^^^^^^^^^^^^^^
  File "C:\Users\luis.vieira\AppData\Local\Programs\Python\Python312\Lib\site-packages\flask_limiter\extension.py", line 1160, in _check_request_limit
    raise e
  File "C:\Users\luis.vieira\AppData\Local\Programs\Python\Python312\Lib\site-packages\flask_limiter\extension.py", line 1157, in _check_request_limit
    self.__evaluate_limits(endpoint, all_limits)
  File "C:\Users\luis.vieira\AppData\Local\Programs\Python\Python312\Lib\site-packages\flask_limiter\extension.py", line 1141, in __evaluate_limits
    raise RateLimitExceeded(
flask_limiter.errors.RateLimitExceeded: 429 Too Many Requests: 30 per 1 hour

2024-10-04 11:26:44,992 INFO [app:92] usuario 1 carregado com sucesso.
2024-10-04 11:27:15,277 INFO [app:92] usuario 1 carregado com sucesso.
2024-10-04 11:27:15,277 INFO [app:188] usuario 1 fez logout.
2024-10-04 11:27:22,314 INFO [app:126] Tentativa de login do usuario: luis
2024-10-04 11:27:22,720 INFO [app:173] usuario luis logado com sucesso.
2024-10-04 11:27:22,830 INFO [app:92] usuario 10 carregado com sucesso.
2024-10-04 11:27:42,958 INFO [app:92] usuario 10 carregado com sucesso.
2024-10-04 11:49:48,602 INFO [csrf:263] The CSRF session token is missing.
2024-10-04 11:49:48,649 ERROR [app:364] Server Error: Traceback (most recent call last):
  File "C:\Users\luis.vieira\AppData\Local\Programs\Python\Python312\Lib\site-packages\flask_wtf\csrf.py", line 261, in protect
    validate_csrf(self._get_csrf_token())
  File "C:\Users\luis.vieira\AppData\Local\Programs\Python\Python312\Lib\site-packages\flask_wtf\csrf.py", line 103, in validate_csrf
    raise ValidationError("The CSRF session token is missing.")
wtforms.validators.ValidationError: The CSRF session token is missing.

During handling of the above exception, another exception occurred:

Traceback (most recent call last):
  File "C:\Users\luis.vieira\AppData\Local\Programs\Python\Python312\Lib\site-packages\flask\app.py", line 878, in full_dispatch_request
    rv = self.preprocess_request()
         ^^^^^^^^^^^^^^^^^^^^^^^^^
  File "C:\Users\luis.vieira\AppData\Local\Programs\Python\Python312\Lib\site-packages\flask\app.py", line 1253, in preprocess_request
    rv = self.ensure_sync(before_func)()
         ^^^^^^^^^^^^^^^^^^^^^^^^^^^^^^^
  File "C:\Users\luis.vieira\AppData\Local\Programs\Python\Python312\Lib\site-packages\flask_wtf\csrf.py", line 229, in csrf_protect
    self.protect()
  File "C:\Users\luis.vieira\AppData\Local\Programs\Python\Python312\Lib\site-packages\flask_wtf\csrf.py", line 264, in protect
    self._error_response(e.args[0])
  File "C:\Users\luis.vieira\AppData\Local\Programs\Python\Python312\Lib\site-packages\flask_wtf\csrf.py", line 307, in _error_response
    raise CSRFError(reason)
flask_wtf.csrf.CSRFError: 400 Bad Request: The CSRF session token is missing.

2024-10-04 11:50:48,608 INFO [csrf:263] The CSRF session token is missing.
2024-10-04 11:50:48,612 ERROR [app:364] Server Error: Traceback (most recent call last):
  File "C:\Users\luis.vieira\AppData\Local\Programs\Python\Python312\Lib\site-packages\flask_wtf\csrf.py", line 261, in protect
    validate_csrf(self._get_csrf_token())
  File "C:\Users\luis.vieira\AppData\Local\Programs\Python\Python312\Lib\site-packages\flask_wtf\csrf.py", line 103, in validate_csrf
    raise ValidationError("The CSRF session token is missing.")
wtforms.validators.ValidationError: The CSRF session token is missing.

During handling of the above exception, another exception occurred:

Traceback (most recent call last):
  File "C:\Users\luis.vieira\AppData\Local\Programs\Python\Python312\Lib\site-packages\flask\app.py", line 878, in full_dispatch_request
    rv = self.preprocess_request()
         ^^^^^^^^^^^^^^^^^^^^^^^^^
  File "C:\Users\luis.vieira\AppData\Local\Programs\Python\Python312\Lib\site-packages\flask\app.py", line 1253, in preprocess_request
    rv = self.ensure_sync(before_func)()
         ^^^^^^^^^^^^^^^^^^^^^^^^^^^^^^^
  File "C:\Users\luis.vieira\AppData\Local\Programs\Python\Python312\Lib\site-packages\flask_wtf\csrf.py", line 229, in csrf_protect
    self.protect()
  File "C:\Users\luis.vieira\AppData\Local\Programs\Python\Python312\Lib\site-packages\flask_wtf\csrf.py", line 264, in protect
    self._error_response(e.args[0])
  File "C:\Users\luis.vieira\AppData\Local\Programs\Python\Python312\Lib\site-packages\flask_wtf\csrf.py", line 307, in _error_response
    raise CSRFError(reason)
flask_wtf.csrf.CSRFError: 400 Bad Request: The CSRF session token is missing.

2024-10-04 11:51:48,641 INFO [csrf:263] The CSRF session token is missing.
2024-10-04 11:51:48,643 ERROR [app:364] Server Error: Traceback (most recent call last):
  File "C:\Users\luis.vieira\AppData\Local\Programs\Python\Python312\Lib\site-packages\flask_wtf\csrf.py", line 261, in protect
    validate_csrf(self._get_csrf_token())
  File "C:\Users\luis.vieira\AppData\Local\Programs\Python\Python312\Lib\site-packages\flask_wtf\csrf.py", line 103, in validate_csrf
    raise ValidationError("The CSRF session token is missing.")
wtforms.validators.ValidationError: The CSRF session token is missing.

During handling of the above exception, another exception occurred:

Traceback (most recent call last):
  File "C:\Users\luis.vieira\AppData\Local\Programs\Python\Python312\Lib\site-packages\flask\app.py", line 878, in full_dispatch_request
    rv = self.preprocess_request()
         ^^^^^^^^^^^^^^^^^^^^^^^^^
  File "C:\Users\luis.vieira\AppData\Local\Programs\Python\Python312\Lib\site-packages\flask\app.py", line 1253, in preprocess_request
    rv = self.ensure_sync(before_func)()
         ^^^^^^^^^^^^^^^^^^^^^^^^^^^^^^^
  File "C:\Users\luis.vieira\AppData\Local\Programs\Python\Python312\Lib\site-packages\flask_wtf\csrf.py", line 229, in csrf_protect
    self.protect()
  File "C:\Users\luis.vieira\AppData\Local\Programs\Python\Python312\Lib\site-packages\flask_wtf\csrf.py", line 264, in protect
    self._error_response(e.args[0])
  File "C:\Users\luis.vieira\AppData\Local\Programs\Python\Python312\Lib\site-packages\flask_wtf\csrf.py", line 307, in _error_response
    raise CSRFError(reason)
flask_wtf.csrf.CSRFError: 400 Bad Request: The CSRF session token is missing.

2024-10-04 11:52:48,307 INFO [csrf:263] The CSRF session token is missing.
2024-10-04 11:52:48,310 ERROR [app:364] Server Error: Traceback (most recent call last):
  File "C:\Users\luis.vieira\AppData\Local\Programs\Python\Python312\Lib\site-packages\flask_wtf\csrf.py", line 261, in protect
    validate_csrf(self._get_csrf_token())
  File "C:\Users\luis.vieira\AppData\Local\Programs\Python\Python312\Lib\site-packages\flask_wtf\csrf.py", line 103, in validate_csrf
    raise ValidationError("The CSRF session token is missing.")
wtforms.validators.ValidationError: The CSRF session token is missing.

During handling of the above exception, another exception occurred:

Traceback (most recent call last):
  File "C:\Users\luis.vieira\AppData\Local\Programs\Python\Python312\Lib\site-packages\flask\app.py", line 878, in full_dispatch_request
    rv = self.preprocess_request()
         ^^^^^^^^^^^^^^^^^^^^^^^^^
  File "C:\Users\luis.vieira\AppData\Local\Programs\Python\Python312\Lib\site-packages\flask\app.py", line 1253, in preprocess_request
    rv = self.ensure_sync(before_func)()
         ^^^^^^^^^^^^^^^^^^^^^^^^^^^^^^^
  File "C:\Users\luis.vieira\AppData\Local\Programs\Python\Python312\Lib\site-packages\flask_wtf\csrf.py", line 229, in csrf_protect
    self.protect()
  File "C:\Users\luis.vieira\AppData\Local\Programs\Python\Python312\Lib\site-packages\flask_wtf\csrf.py", line 264, in protect
    self._error_response(e.args[0])
  File "C:\Users\luis.vieira\AppData\Local\Programs\Python\Python312\Lib\site-packages\flask_wtf\csrf.py", line 307, in _error_response
    raise CSRFError(reason)
flask_wtf.csrf.CSRFError: 400 Bad Request: The CSRF session token is missing.

2024-10-04 11:53:48,301 INFO [csrf:263] The CSRF session token is missing.
2024-10-04 11:53:48,304 ERROR [app:364] Server Error: Traceback (most recent call last):
  File "C:\Users\luis.vieira\AppData\Local\Programs\Python\Python312\Lib\site-packages\flask_wtf\csrf.py", line 261, in protect
    validate_csrf(self._get_csrf_token())
  File "C:\Users\luis.vieira\AppData\Local\Programs\Python\Python312\Lib\site-packages\flask_wtf\csrf.py", line 103, in validate_csrf
    raise ValidationError("The CSRF session token is missing.")
wtforms.validators.ValidationError: The CSRF session token is missing.

During handling of the above exception, another exception occurred:

Traceback (most recent call last):
  File "C:\Users\luis.vieira\AppData\Local\Programs\Python\Python312\Lib\site-packages\flask\app.py", line 878, in full_dispatch_request
    rv = self.preprocess_request()
         ^^^^^^^^^^^^^^^^^^^^^^^^^
  File "C:\Users\luis.vieira\AppData\Local\Programs\Python\Python312\Lib\site-packages\flask\app.py", line 1253, in preprocess_request
    rv = self.ensure_sync(before_func)()
         ^^^^^^^^^^^^^^^^^^^^^^^^^^^^^^^
  File "C:\Users\luis.vieira\AppData\Local\Programs\Python\Python312\Lib\site-packages\flask_wtf\csrf.py", line 229, in csrf_protect
    self.protect()
  File "C:\Users\luis.vieira\AppData\Local\Programs\Python\Python312\Lib\site-packages\flask_wtf\csrf.py", line 264, in protect
    self._error_response(e.args[0])
  File "C:\Users\luis.vieira\AppData\Local\Programs\Python\Python312\Lib\site-packages\flask_wtf\csrf.py", line 307, in _error_response
    raise CSRFError(reason)
flask_wtf.csrf.CSRFError: 400 Bad Request: The CSRF session token is missing.

2024-10-04 11:54:03,068 INFO [csrf:263] The CSRF session token is missing.
2024-10-04 11:54:03,071 ERROR [app:364] Server Error: Traceback (most recent call last):
  File "C:\Users\luis.vieira\AppData\Local\Programs\Python\Python312\Lib\site-packages\flask_wtf\csrf.py", line 261, in protect
    validate_csrf(self._get_csrf_token())
  File "C:\Users\luis.vieira\AppData\Local\Programs\Python\Python312\Lib\site-packages\flask_wtf\csrf.py", line 103, in validate_csrf
    raise ValidationError("The CSRF session token is missing.")
wtforms.validators.ValidationError: The CSRF session token is missing.

During handling of the above exception, another exception occurred:

Traceback (most recent call last):
  File "C:\Users\luis.vieira\AppData\Local\Programs\Python\Python312\Lib\site-packages\flask\app.py", line 878, in full_dispatch_request
    rv = self.preprocess_request()
         ^^^^^^^^^^^^^^^^^^^^^^^^^
  File "C:\Users\luis.vieira\AppData\Local\Programs\Python\Python312\Lib\site-packages\flask\app.py", line 1253, in preprocess_request
    rv = self.ensure_sync(before_func)()
         ^^^^^^^^^^^^^^^^^^^^^^^^^^^^^^^
  File "C:\Users\luis.vieira\AppData\Local\Programs\Python\Python312\Lib\site-packages\flask_wtf\csrf.py", line 229, in csrf_protect
    self.protect()
  File "C:\Users\luis.vieira\AppData\Local\Programs\Python\Python312\Lib\site-packages\flask_wtf\csrf.py", line 264, in protect
    self._error_response(e.args[0])
  File "C:\Users\luis.vieira\AppData\Local\Programs\Python\Python312\Lib\site-packages\flask_wtf\csrf.py", line 307, in _error_response
    raise CSRFError(reason)
flask_wtf.csrf.CSRFError: 400 Bad Request: The CSRF session token is missing.

2024-10-04 12:17:17,380 INFO [wasyncore:485] Serving on http://0.0.0.0:8279
2024-10-04 12:19:48,762 INFO [csrf:263] The CSRF session token is missing.
2024-10-04 12:19:57,979 INFO [app:127] Tentativa de login do usuario: luis
2024-10-04 12:19:58,346 INFO [app:174] usuario luis logado com sucesso.
2024-10-04 12:19:58,370 INFO [app:93] usuario 10 carregado com sucesso.
2024-10-04 12:20:03,725 INFO [app:93] usuario 10 carregado com sucesso.
2024-10-04 12:20:07,627 INFO [app:93] usuario 10 carregado com sucesso.
2024-10-04 12:20:08,456 INFO [app:93] usuario 10 carregado com sucesso.
2024-10-04 12:20:11,227 INFO [app:93] usuario 10 carregado com sucesso.
2024-10-04 12:20:12,194 INFO [app:93] usuario 10 carregado com sucesso.
2024-10-04 12:20:15,412 INFO [app:93] usuario 10 carregado com sucesso.
2024-10-04 12:20:16,211 INFO [app:93] usuario 10 carregado com sucesso.
2024-10-04 12:20:36,602 INFO [app:93] usuario 10 carregado com sucesso.
2024-10-04 12:30:42,576 INFO [csrf:263] The CSRF session token is missing.
2024-10-04 12:44:32,178 INFO [csrf:263] The CSRF session token is missing.
2024-10-04 12:44:43,047 INFO [app:127] Tentativa de login do usuario: luis
2024-10-04 12:44:43,412 INFO [app:174] usuario luis logado com sucesso.
2024-10-04 12:44:43,440 INFO [app:93] usuario 10 carregado com sucesso.
2024-10-04 12:45:27,009 INFO [app:93] usuario 10 carregado com sucesso.
2024-10-04 12:54:18,847 INFO [wasyncore:485] Serving on http://0.0.0.0:8279
2024-10-04 12:54:42,207 INFO [app:93] usuario 10 carregado com sucesso.
2024-10-04 13:54:04,983 INFO [csrf:263] The CSRF session token is missing.
2024-10-04 13:54:04,991 INFO [app:364] Um usuário não autenticado foi deslogado por inatividade
2024-10-04 13:54:13,188 INFO [app:127] Tentativa de login do usuario: luis
2024-10-04 13:54:13,542 INFO [app:174] usuario luis logado com sucesso.
2024-10-04 13:54:13,570 INFO [app:93] usuario 10 carregado com sucesso.
2024-10-04 14:04:19,554 INFO [csrf:263] The CSRF session token is missing.
2024-10-04 14:04:19,558 INFO [app:364] Um usuário não autenticado foi deslogado por inatividade
2024-10-04 14:41:18,343 INFO [csrf:263] The CSRF session token is missing.
2024-10-04 14:41:18,344 INFO [app:364] Um usuário não autenticado foi deslogado por inatividade
2024-10-07 13:17:03,153 INFO [wasyncore:485] Serving on http://0.0.0.0:8279
2024-10-07 13:17:04,986 WARNING [app:377] Página não encontrada: http://localhost:8279/favicon.ico
2024-10-07 13:17:09,567 INFO [app:127] Tentativa de login do usuario: luis
2024-10-07 13:17:10,475 INFO [app:174] usuario luis logado com sucesso.
2024-10-07 13:17:10,600 INFO [app:93] usuario 10 carregado com sucesso.
2024-10-07 13:17:19,707 INFO [app:93] usuario 10 carregado com sucesso.
2024-10-07 13:18:10,101 INFO [app:93] usuario 10 carregado com sucesso.
2024-10-07 13:19:26,416 INFO [app:93] usuario 10 carregado com sucesso.
2024-10-07 13:19:28,037 INFO [app:93] usuario 10 carregado com sucesso.
2024-10-07 13:19:55,463 INFO [app:93] usuario 10 carregado com sucesso.
2024-10-07 13:20:32,761 INFO [app:93] usuario 10 carregado com sucesso.
2024-10-07 13:30:39,160 INFO [csrf:263] The CSRF session token is missing.
2024-10-07 13:30:39,161 INFO [app:364] Um usuário não autenticado foi deslogado por inatividade
2024-10-10 09:55:20,391 INFO [wasyncore:485] Serving on http://0.0.0.0:8279
2024-10-10 09:55:27,104 WARNING [app:377] Página não encontrada: http://localhost:8279/favicon.ico
2024-10-10 09:55:35,538 INFO [app:127] Tentativa de login do usuario: jockey
2024-10-10 09:55:36,140 INFO [app:174] usuario jockey logado com sucesso.
2024-10-10 09:55:36,250 INFO [app:93] usuario 1 carregado com sucesso.
2024-10-10 09:55:39,812 INFO [app:93] usuario 1 carregado com sucesso.
2024-10-10 09:55:45,866 INFO [app:93] usuario 1 carregado com sucesso.
2024-10-10 09:55:46,266 WARNING [app:377] Página não encontrada: http://localhost:8279/favicon.ico
2024-10-10 09:55:46,289 INFO [app:93] usuario 1 carregado com sucesso.
2024-10-10 09:55:55,519 INFO [app:93] usuario 1 carregado com sucesso.
2024-10-10 09:55:55,519 INFO [app:189] usuario 1 fez logout.
2024-10-10 09:56:32,944 INFO [app:127] Tentativa de login do usuario: jockey
2024-10-10 09:56:33,347 INFO [app:174] usuario jockey logado com sucesso.
2024-10-10 09:56:33,373 INFO [app:93] usuario 1 carregado com sucesso.
2024-10-10 09:56:35,011 INFO [app:93] usuario 1 carregado com sucesso.
2024-10-10 10:12:25,282 INFO [csrf:263] The CSRF session token is missing.
2024-10-10 10:12:25,284 INFO [app:364] Um usuário não autenticado foi deslogado por inatividade
2024-10-10 10:16:19,283 INFO [app:127] Tentativa de login do usuario: luis
2024-10-10 10:16:19,641 INFO [app:174] usuario luis logado com sucesso.
2024-10-10 10:16:19,668 INFO [app:93] usuario 10 carregado com sucesso.
2024-10-10 10:16:21,378 INFO [app:93] usuario 10 carregado com sucesso.
2024-10-10 10:17:32,731 INFO [app:93] usuario 10 carregado com sucesso.
2024-10-10 10:17:34,003 INFO [app:93] usuario 10 carregado com sucesso.
2024-10-10 10:49:44,966 INFO [csrf:263] The CSRF session token is missing.
2024-10-10 10:49:44,972 INFO [app:364] Um usuário não autenticado foi deslogado por inatividade
2024-10-10 17:04:32,629 INFO [wasyncore:485] Serving on http://0.0.0.0:8279
2024-10-10 17:05:55,105 WARNING [app:378] Página não encontrada: http://localhost:8279/favicon.ico
2024-10-10 17:06:00,708 INFO [app:128] Tentativa de login do usuario: luis
2024-10-10 17:06:01,103 INFO [app:175] usuario luis logado com sucesso.
2024-10-10 17:06:01,123 INFO [app:93] usuario 10 carregado com sucesso.
2024-10-10 17:06:02,409 INFO [app:93] usuario 10 carregado com sucesso.
2024-10-10 17:14:16,306 INFO [app:93] usuario 10 carregado com sucesso.
2024-10-10 17:22:07,301 INFO [app:93] usuario 10 carregado com sucesso.
2024-10-10 17:22:08,254 INFO [app:93] usuario 10 carregado com sucesso.
2024-10-10 17:22:20,165 INFO [wasyncore:485] Serving on http://0.0.0.0:8279
2024-10-28 16:15:31,123 INFO [wasyncore:485] Serving on http://0.0.0.0:8279
2024-10-28 16:15:38,043 WARNING [app:385] Página não encontrada: http://localhost:8279/favicon.ico
2024-10-28 16:15:41,955 INFO [app:129] Tentativa de login do usuario: luis
2024-10-28 16:15:47,974 ERROR [app:380] Server Error: Traceback (most recent call last):
  File "C:\Users\luis.vieira\AppData\Local\Programs\Python\Python312\Lib\site-packages\flask\app.py", line 880, in full_dispatch_request
    rv = self.dispatch_request()
         ^^^^^^^^^^^^^^^^^^^^^^^
  File "C:\Users\luis.vieira\AppData\Local\Programs\Python\Python312\Lib\site-packages\flask\app.py", line 865, in dispatch_request
    return self.ensure_sync(self.view_functions[rule.endpoint])(**view_args)  # type: ignore[no-any-return]
           ^^^^^^^^^^^^^^^^^^^^^^^^^^^^^^^^^^^^^^^^^^^^^^^^^^^^^^^^^^^^^^^^^
  File "C:\Users\luis.vieira\AppData\Local\Programs\Python\Python312\Lib\site-packages\flask_limiter\extension.py", line 1303, in __inner
    return cast(R, flask.current_app.ensure_sync(obj)(*a, **k))
                   ^^^^^^^^^^^^^^^^^^^^^^^^^^^^^^^^^^^^^^^^^^^
  File "C:\Users\luis.vieira\Documents\GitHub\Flask4\app.py", line 151, in login
    if not stored_password.startswith('$2b$'):
           ^^^^^^^^^^^^^^^^^^^^^^^^^^
AttributeError: 'NoneType' object has no attribute 'startswith'

2024-10-28 16:15:58,077 INFO [app:129] Tentativa de login do usuario: luis
2024-10-28 16:15:58,101 ERROR [app:380] Server Error: Traceback (most recent call last):
  File "C:\Users\luis.vieira\AppData\Local\Programs\Python\Python312\Lib\site-packages\flask\app.py", line 880, in full_dispatch_request
    rv = self.dispatch_request()
         ^^^^^^^^^^^^^^^^^^^^^^^
  File "C:\Users\luis.vieira\AppData\Local\Programs\Python\Python312\Lib\site-packages\flask\app.py", line 865, in dispatch_request
    return self.ensure_sync(self.view_functions[rule.endpoint])(**view_args)  # type: ignore[no-any-return]
           ^^^^^^^^^^^^^^^^^^^^^^^^^^^^^^^^^^^^^^^^^^^^^^^^^^^^^^^^^^^^^^^^^
  File "C:\Users\luis.vieira\AppData\Local\Programs\Python\Python312\Lib\site-packages\flask_limiter\extension.py", line 1303, in __inner
    return cast(R, flask.current_app.ensure_sync(obj)(*a, **k))
                   ^^^^^^^^^^^^^^^^^^^^^^^^^^^^^^^^^^^^^^^^^^^
  File "C:\Users\luis.vieira\Documents\GitHub\Flask4\app.py", line 151, in login
    if not stored_password.startswith('$2b$'):
           ^^^^^^^^^^^^^^^^^^^^^^^^^^
AttributeError: 'NoneType' object has no attribute 'startswith'

2024-10-28 16:16:08,092 INFO [app:129] Tentativa de login do usuario: luis
2024-10-28 16:16:08,116 ERROR [app:380] Server Error: Traceback (most recent call last):
  File "C:\Users\luis.vieira\AppData\Local\Programs\Python\Python312\Lib\site-packages\flask\app.py", line 880, in full_dispatch_request
    rv = self.dispatch_request()
         ^^^^^^^^^^^^^^^^^^^^^^^
  File "C:\Users\luis.vieira\AppData\Local\Programs\Python\Python312\Lib\site-packages\flask\app.py", line 865, in dispatch_request
    return self.ensure_sync(self.view_functions[rule.endpoint])(**view_args)  # type: ignore[no-any-return]
           ^^^^^^^^^^^^^^^^^^^^^^^^^^^^^^^^^^^^^^^^^^^^^^^^^^^^^^^^^^^^^^^^^
  File "C:\Users\luis.vieira\AppData\Local\Programs\Python\Python312\Lib\site-packages\flask_limiter\extension.py", line 1303, in __inner
    return cast(R, flask.current_app.ensure_sync(obj)(*a, **k))
                   ^^^^^^^^^^^^^^^^^^^^^^^^^^^^^^^^^^^^^^^^^^^
  File "C:\Users\luis.vieira\Documents\GitHub\Flask4\app.py", line 151, in login
    # Se a senha não for um hash bcrypt, hashear e atualizar no banco
       ^^^^^^^^^^^^^^^^^^^^^^^^^
AttributeError: 'NoneType' object has no attribute 'startswith'

2024-10-28 16:16:50,489 INFO [wasyncore:485] Serving on http://0.0.0.0:8279
2024-10-28 16:16:56,342 INFO [app:128] Tentativa de login do usuario: luis
2024-10-28 16:16:56,395 ERROR [app:373] Server Error: Traceback (most recent call last):
  File "C:\Users\luis.vieira\AppData\Local\Programs\Python\Python312\Lib\site-packages\flask\app.py", line 880, in full_dispatch_request
    rv = self.dispatch_request()
         ^^^^^^^^^^^^^^^^^^^^^^^
  File "C:\Users\luis.vieira\AppData\Local\Programs\Python\Python312\Lib\site-packages\flask\app.py", line 865, in dispatch_request
    return self.ensure_sync(self.view_functions[rule.endpoint])(**view_args)  # type: ignore[no-any-return]
           ^^^^^^^^^^^^^^^^^^^^^^^^^^^^^^^^^^^^^^^^^^^^^^^^^^^^^^^^^^^^^^^^^
  File "C:\Users\luis.vieira\AppData\Local\Programs\Python\Python312\Lib\site-packages\flask_limiter\extension.py", line 1303, in __inner
    return cast(R, flask.current_app.ensure_sync(obj)(*a, **k))
                   ^^^^^^^^^^^^^^^^^^^^^^^^^^^^^^^^^^^^^^^^^^^
  File "C:\Users\luis.vieira\Documents\GitHub\Flask4\app.py", line 150, in login
    if not stored_password.startswith('$2b$'):
           ^^^^^^^^^^^^^^^^^^^^^^^^^^
AttributeError: 'NoneType' object has no attribute 'startswith'

2024-10-28 16:17:04,946 INFO [app:128] Tentativa de login do usuario: luis
2024-10-28 16:17:04,969 ERROR [app:373] Server Error: Traceback (most recent call last):
  File "C:\Users\luis.vieira\AppData\Local\Programs\Python\Python312\Lib\site-packages\flask\app.py", line 880, in full_dispatch_request
    rv = self.dispatch_request()
         ^^^^^^^^^^^^^^^^^^^^^^^
  File "C:\Users\luis.vieira\AppData\Local\Programs\Python\Python312\Lib\site-packages\flask\app.py", line 865, in dispatch_request
    return self.ensure_sync(self.view_functions[rule.endpoint])(**view_args)  # type: ignore[no-any-return]
           ^^^^^^^^^^^^^^^^^^^^^^^^^^^^^^^^^^^^^^^^^^^^^^^^^^^^^^^^^^^^^^^^^
  File "C:\Users\luis.vieira\AppData\Local\Programs\Python\Python312\Lib\site-packages\flask_limiter\extension.py", line 1303, in __inner
    return cast(R, flask.current_app.ensure_sync(obj)(*a, **k))
                   ^^^^^^^^^^^^^^^^^^^^^^^^^^^^^^^^^^^^^^^^^^^
  File "C:\Users\luis.vieira\Documents\GitHub\Flask4\app.py", line 150, in login
    if not stored_password.startswith('$2b$'):
           ^^^^^^^^^^^^^^^^^^^^^^^^^^
AttributeError: 'NoneType' object has no attribute 'startswith'

2024-10-29 15:11:33,139 INFO [wasyncore:485] Serving on http://0.0.0.0:8279
2024-10-29 15:46:48,763 WARNING [app:378] Página não encontrada: http://localhost:8279/favicon.ico
2024-10-29 15:46:52,749 INFO [app:128] Tentativa de login do usuario: luis
2024-10-29 15:46:52,960 ERROR [app:373] Server Error: Traceback (most recent call last):
  File "C:\Users\luis.vieira\AppData\Local\Programs\Python\Python312\Lib\site-packages\flask\app.py", line 880, in full_dispatch_request
    rv = self.dispatch_request()
         ^^^^^^^^^^^^^^^^^^^^^^^
  File "C:\Users\luis.vieira\AppData\Local\Programs\Python\Python312\Lib\site-packages\flask\app.py", line 865, in dispatch_request
    return self.ensure_sync(self.view_functions[rule.endpoint])(**view_args)  # type: ignore[no-any-return]
           ^^^^^^^^^^^^^^^^^^^^^^^^^^^^^^^^^^^^^^^^^^^^^^^^^^^^^^^^^^^^^^^^^
  File "C:\Users\luis.vieira\AppData\Local\Programs\Python\Python312\Lib\site-packages\flask_limiter\extension.py", line 1303, in __inner
    return cast(R, flask.current_app.ensure_sync(obj)(*a, **k))
                   ^^^^^^^^^^^^^^^^^^^^^^^^^^^^^^^^^^^^^^^^^^^
  File "C:\Users\luis.vieira\Documents\GitHub\Flask4\app.py", line 150, in login
    if not stored_password.startswith('$2b$'):
           ^^^^^^^^^^^^^^^^^^^^^^^^^^
AttributeError: 'NoneType' object has no attribute 'startswith'

2024-10-29 15:47:20,512 INFO [wasyncore:485] Serving on http://0.0.0.0:8279
2024-10-29 15:47:26,917 WARNING [app:378] Página não encontrada: http://localhost:8279/favicon.ico
2024-10-29 15:47:32,141 INFO [app:128] Tentativa de login do usuario: luis
2024-10-29 15:47:32,190 ERROR [app:373] Server Error: Traceback (most recent call last):
  File "C:\Users\luis.vieira\AppData\Local\Programs\Python\Python312\Lib\site-packages\flask\app.py", line 880, in full_dispatch_request
    rv = self.dispatch_request()
         ^^^^^^^^^^^^^^^^^^^^^^^
  File "C:\Users\luis.vieira\AppData\Local\Programs\Python\Python312\Lib\site-packages\flask\app.py", line 865, in dispatch_request
    return self.ensure_sync(self.view_functions[rule.endpoint])(**view_args)  # type: ignore[no-any-return]
           ^^^^^^^^^^^^^^^^^^^^^^^^^^^^^^^^^^^^^^^^^^^^^^^^^^^^^^^^^^^^^^^^^
  File "C:\Users\luis.vieira\AppData\Local\Programs\Python\Python312\Lib\site-packages\flask_limiter\extension.py", line 1303, in __inner
    return cast(R, flask.current_app.ensure_sync(obj)(*a, **k))
                   ^^^^^^^^^^^^^^^^^^^^^^^^^^^^^^^^^^^^^^^^^^^
  File "C:\Users\luis.vieira\Documents\GitHub\Flask4\app.py", line 150, in login
    if not stored_password.startswith('$2b$'):
           ^^^^^^^^^^^^^^^^^^^^^^^^^^
AttributeError: 'NoneType' object has no attribute 'startswith'

2024-10-29 15:47:43,095 INFO [extension:1095] ratelimit 5 per 1 minute (127.0.0.1) exceeded at endpoint: login
2024-10-29 15:47:43,097 ERROR [app:373] Server Error: Traceback (most recent call last):
  File "C:\Users\luis.vieira\AppData\Local\Programs\Python\Python312\Lib\site-packages\flask\app.py", line 880, in full_dispatch_request
    rv = self.dispatch_request()
         ^^^^^^^^^^^^^^^^^^^^^^^
  File "C:\Users\luis.vieira\AppData\Local\Programs\Python\Python312\Lib\site-packages\flask\app.py", line 865, in dispatch_request
    return self.ensure_sync(self.view_functions[rule.endpoint])(**view_args)  # type: ignore[no-any-return]
           ^^^^^^^^^^^^^^^^^^^^^^^^^^^^^^^^^^^^^^^^^^^^^^^^^^^^^^^^^^^^^^^^^
  File "C:\Users\luis.vieira\AppData\Local\Programs\Python\Python312\Lib\site-packages\flask_limiter\extension.py", line 1299, in __inner
    self.limiter._check_request_limit(
  File "C:\Users\luis.vieira\AppData\Local\Programs\Python\Python312\Lib\site-packages\flask_limiter\extension.py", line 1160, in _check_request_limit
    raise e
  File "C:\Users\luis.vieira\AppData\Local\Programs\Python\Python312\Lib\site-packages\flask_limiter\extension.py", line 1157, in _check_request_limit
    self.__evaluate_limits(endpoint, all_limits)
  File "C:\Users\luis.vieira\AppData\Local\Programs\Python\Python312\Lib\site-packages\flask_limiter\extension.py", line 1141, in __evaluate_limits
    raise RateLimitExceeded(
flask_limiter.errors.RateLimitExceeded: 429 Too Many Requests: 5 per 1 minute

2024-11-06 08:45:04,771 INFO [wasyncore:485] Serving on http://0.0.0.0:8279
2024-11-06 09:25:06,780 INFO [wasyncore:485] Serving on http://0.0.0.0:8279
2024-11-06 09:27:54,203 INFO [wasyncore:485] Serving on http://0.0.0.0:8279
2024-11-06 10:34:43,389 INFO [wasyncore:485] Serving on http://0.0.0.0:8279
2024-11-06 10:46:58,298 INFO [wasyncore:485] Serving on http://0.0.0.0:8279
2024-11-06 10:48:05,450 WARNING [app:378] Página não encontrada: http://localhost:8279/favicon.ico
2024-11-06 10:48:07,442 WARNING [app:378] Página não encontrada: http://localhost:8279/favicon.ico
2024-11-06 10:48:11,456 INFO [app:128] Tentativa de login do usuario: luis
2024-11-06 10:48:11,989 INFO [app:175] usuario luis logado com sucesso.
2024-11-06 10:48:12,010 INFO [app:93] usuario 2 carregado com sucesso.
2024-11-06 10:48:13,031 INFO [app:93] usuario 2 carregado com sucesso.
2024-11-06 10:48:27,056 INFO [app:93] usuario 2 carregado com sucesso.
2024-11-06 10:48:30,002 INFO [app:93] usuario 2 carregado com sucesso.
2024-11-06 10:49:08,251 INFO [wasyncore:485] Serving on http://0.0.0.0:8279
2024-11-06 10:49:16,029 INFO [app:93] usuario 2 carregado com sucesso.
2024-11-06 10:49:16,030 INFO [app:190] usuario 2 fez logout.
2024-11-06 10:49:21,098 INFO [app:128] Tentativa de login do usuario: luis
2024-11-06 10:49:21,452 INFO [app:175] usuario luis logado com sucesso.
2024-11-06 10:49:21,473 INFO [app:93] usuario 2 carregado com sucesso.
2024-11-06 10:49:23,175 INFO [app:93] usuario 2 carregado com sucesso.
2024-11-06 11:03:27,795 INFO [csrf:263] The CSRF session token is missing.
2024-11-06 11:03:27,796 INFO [app:365] Um usuário não autenticado foi deslogado por inatividade
2024-11-06 11:07:44,507 INFO [wasyncore:485] Serving on http://0.0.0.0:8279
2024-11-06 11:08:00,206 INFO [app:128] Tentativa de login do usuario: luis
2024-11-06 11:08:00,582 INFO [app:175] usuario luis logado com sucesso.
2024-11-06 11:08:00,607 INFO [app:93] usuario 2 carregado com sucesso.
2024-11-06 11:08:02,489 INFO [app:93] usuario 2 carregado com sucesso.
2024-11-06 11:08:54,633 INFO [wasyncore:485] Serving on http://0.0.0.0:8279
2024-11-06 11:08:56,285 INFO [app:93] usuario 2 carregado com sucesso.
2024-11-06 11:19:02,801 INFO [csrf:263] The CSRF session token is missing.
2024-11-06 11:19:02,802 INFO [app:365] Um usuário não autenticado foi deslogado por inatividade
2024-11-06 11:21:05,326 INFO [wasyncore:485] Serving on http://0.0.0.0:8279
2024-11-06 11:21:16,438 INFO [extension:1095] ratelimit 5 per 1 minute (127.0.0.1) exceeded at endpoint: login
2024-11-06 11:21:16,446 ERROR [app:373] Server Error: Traceback (most recent call last):
  File "C:\Users\luis.vieira\AppData\Local\Programs\Python\Python312\Lib\site-packages\flask\app.py", line 880, in full_dispatch_request
    rv = self.dispatch_request()
         ^^^^^^^^^^^^^^^^^^^^^^^
  File "C:\Users\luis.vieira\AppData\Local\Programs\Python\Python312\Lib\site-packages\flask\app.py", line 865, in dispatch_request
    return self.ensure_sync(self.view_functions[rule.endpoint])(**view_args)  # type: ignore[no-any-return]
           ^^^^^^^^^^^^^^^^^^^^^^^^^^^^^^^^^^^^^^^^^^^^^^^^^^^^^^^^^^^^^^^^^
  File "C:\Users\luis.vieira\AppData\Local\Programs\Python\Python312\Lib\site-packages\flask_limiter\extension.py", line 1299, in __inner
    self.limiter._check_request_limit(
  File "C:\Users\luis.vieira\AppData\Local\Programs\Python\Python312\Lib\site-packages\flask_limiter\extension.py", line 1160, in _check_request_limit
    raise e
  File "C:\Users\luis.vieira\AppData\Local\Programs\Python\Python312\Lib\site-packages\flask_limiter\extension.py", line 1157, in _check_request_limit
    self.__evaluate_limits(endpoint, all_limits)
  File "C:\Users\luis.vieira\AppData\Local\Programs\Python\Python312\Lib\site-packages\flask_limiter\extension.py", line 1141, in __evaluate_limits
    raise RateLimitExceeded(
flask_limiter.errors.RateLimitExceeded: 429 Too Many Requests: 5 per 1 minute

2024-11-06 11:21:16,485 WARNING [app:378] Página não encontrada: http://localhost:8279/favicon.ico
2024-11-06 11:21:16,595 INFO [extension:1095] ratelimit 5 per 1 minute (127.0.0.1) exceeded at endpoint: login
2024-11-06 11:21:16,598 ERROR [app:373] Server Error: Traceback (most recent call last):
  File "C:\Users\luis.vieira\AppData\Local\Programs\Python\Python312\Lib\site-packages\flask\app.py", line 880, in full_dispatch_request
    rv = self.dispatch_request()
         ^^^^^^^^^^^^^^^^^^^^^^^
  File "C:\Users\luis.vieira\AppData\Local\Programs\Python\Python312\Lib\site-packages\flask\app.py", line 865, in dispatch_request
    return self.ensure_sync(self.view_functions[rule.endpoint])(**view_args)  # type: ignore[no-any-return]
           ^^^^^^^^^^^^^^^^^^^^^^^^^^^^^^^^^^^^^^^^^^^^^^^^^^^^^^^^^^^^^^^^^
  File "C:\Users\luis.vieira\AppData\Local\Programs\Python\Python312\Lib\site-packages\flask_limiter\extension.py", line 1299, in __inner
    self.limiter._check_request_limit(
  File "C:\Users\luis.vieira\AppData\Local\Programs\Python\Python312\Lib\site-packages\flask_limiter\extension.py", line 1160, in _check_request_limit
    raise e
  File "C:\Users\luis.vieira\AppData\Local\Programs\Python\Python312\Lib\site-packages\flask_limiter\extension.py", line 1157, in _check_request_limit
    self.__evaluate_limits(endpoint, all_limits)
  File "C:\Users\luis.vieira\AppData\Local\Programs\Python\Python312\Lib\site-packages\flask_limiter\extension.py", line 1141, in __evaluate_limits
    raise RateLimitExceeded(
flask_limiter.errors.RateLimitExceeded: 429 Too Many Requests: 5 per 1 minute

2024-11-06 11:21:16,629 WARNING [app:378] Página não encontrada: http://localhost:8279/favicon.ico
2024-11-06 11:21:19,256 INFO [extension:1095] ratelimit 5 per 1 minute (127.0.0.1) exceeded at endpoint: login
2024-11-06 11:21:19,259 ERROR [app:373] Server Error: Traceback (most recent call last):
  File "C:\Users\luis.vieira\AppData\Local\Programs\Python\Python312\Lib\site-packages\flask\app.py", line 880, in full_dispatch_request
    rv = self.dispatch_request()
         ^^^^^^^^^^^^^^^^^^^^^^^
  File "C:\Users\luis.vieira\AppData\Local\Programs\Python\Python312\Lib\site-packages\flask\app.py", line 865, in dispatch_request
    return self.ensure_sync(self.view_functions[rule.endpoint])(**view_args)  # type: ignore[no-any-return]
           ^^^^^^^^^^^^^^^^^^^^^^^^^^^^^^^^^^^^^^^^^^^^^^^^^^^^^^^^^^^^^^^^^
  File "C:\Users\luis.vieira\AppData\Local\Programs\Python\Python312\Lib\site-packages\flask_limiter\extension.py", line 1299, in __inner
    self.limiter._check_request_limit(
  File "C:\Users\luis.vieira\AppData\Local\Programs\Python\Python312\Lib\site-packages\flask_limiter\extension.py", line 1160, in _check_request_limit
    raise e
  File "C:\Users\luis.vieira\AppData\Local\Programs\Python\Python312\Lib\site-packages\flask_limiter\extension.py", line 1157, in _check_request_limit
    self.__evaluate_limits(endpoint, all_limits)
  File "C:\Users\luis.vieira\AppData\Local\Programs\Python\Python312\Lib\site-packages\flask_limiter\extension.py", line 1141, in __evaluate_limits
    raise RateLimitExceeded(
flask_limiter.errors.RateLimitExceeded: 429 Too Many Requests: 5 per 1 minute

2024-11-06 11:21:22,241 INFO [extension:1095] ratelimit 5 per 1 minute (127.0.0.1) exceeded at endpoint: login
2024-11-06 11:21:22,243 ERROR [app:373] Server Error: Traceback (most recent call last):
  File "C:\Users\luis.vieira\AppData\Local\Programs\Python\Python312\Lib\site-packages\flask\app.py", line 880, in full_dispatch_request
    rv = self.dispatch_request()
         ^^^^^^^^^^^^^^^^^^^^^^^
  File "C:\Users\luis.vieira\AppData\Local\Programs\Python\Python312\Lib\site-packages\flask\app.py", line 865, in dispatch_request
    return self.ensure_sync(self.view_functions[rule.endpoint])(**view_args)  # type: ignore[no-any-return]
           ^^^^^^^^^^^^^^^^^^^^^^^^^^^^^^^^^^^^^^^^^^^^^^^^^^^^^^^^^^^^^^^^^
  File "C:\Users\luis.vieira\AppData\Local\Programs\Python\Python312\Lib\site-packages\flask_limiter\extension.py", line 1299, in __inner
    self.limiter._check_request_limit(
  File "C:\Users\luis.vieira\AppData\Local\Programs\Python\Python312\Lib\site-packages\flask_limiter\extension.py", line 1160, in _check_request_limit
    raise e
  File "C:\Users\luis.vieira\AppData\Local\Programs\Python\Python312\Lib\site-packages\flask_limiter\extension.py", line 1157, in _check_request_limit
    self.__evaluate_limits(endpoint, all_limits)
  File "C:\Users\luis.vieira\AppData\Local\Programs\Python\Python312\Lib\site-packages\flask_limiter\extension.py", line 1141, in __evaluate_limits
    raise RateLimitExceeded(
flask_limiter.errors.RateLimitExceeded: 429 Too Many Requests: 5 per 1 minute

2024-11-06 11:21:25,397 INFO [extension:1095] ratelimit 5 per 1 minute (127.0.0.1) exceeded at endpoint: login
2024-11-06 11:21:25,398 ERROR [app:373] Server Error: Traceback (most recent call last):
  File "C:\Users\luis.vieira\AppData\Local\Programs\Python\Python312\Lib\site-packages\flask\app.py", line 880, in full_dispatch_request
    rv = self.dispatch_request()
         ^^^^^^^^^^^^^^^^^^^^^^^
  File "C:\Users\luis.vieira\AppData\Local\Programs\Python\Python312\Lib\site-packages\flask\app.py", line 865, in dispatch_request
    return self.ensure_sync(self.view_functions[rule.endpoint])(**view_args)  # type: ignore[no-any-return]
           ^^^^^^^^^^^^^^^^^^^^^^^^^^^^^^^^^^^^^^^^^^^^^^^^^^^^^^^^^^^^^^^^^
  File "C:\Users\luis.vieira\AppData\Local\Programs\Python\Python312\Lib\site-packages\flask_limiter\extension.py", line 1299, in __inner
    self.limiter._check_request_limit(
  File "C:\Users\luis.vieira\AppData\Local\Programs\Python\Python312\Lib\site-packages\flask_limiter\extension.py", line 1160, in _check_request_limit
    raise e
  File "C:\Users\luis.vieira\AppData\Local\Programs\Python\Python312\Lib\site-packages\flask_limiter\extension.py", line 1157, in _check_request_limit
    self.__evaluate_limits(endpoint, all_limits)
  File "C:\Users\luis.vieira\AppData\Local\Programs\Python\Python312\Lib\site-packages\flask_limiter\extension.py", line 1141, in __evaluate_limits
    raise RateLimitExceeded(
flask_limiter.errors.RateLimitExceeded: 429 Too Many Requests: 5 per 1 minute

2024-11-06 11:21:36,481 INFO [extension:1095] ratelimit 5 per 1 minute (127.0.0.1) exceeded at endpoint: login
2024-11-06 11:21:36,482 ERROR [app:373] Server Error: Traceback (most recent call last):
  File "C:\Users\luis.vieira\AppData\Local\Programs\Python\Python312\Lib\site-packages\flask\app.py", line 880, in full_dispatch_request
    rv = self.dispatch_request()
         ^^^^^^^^^^^^^^^^^^^^^^^
  File "C:\Users\luis.vieira\AppData\Local\Programs\Python\Python312\Lib\site-packages\flask\app.py", line 865, in dispatch_request
    return self.ensure_sync(self.view_functions[rule.endpoint])(**view_args)  # type: ignore[no-any-return]
           ^^^^^^^^^^^^^^^^^^^^^^^^^^^^^^^^^^^^^^^^^^^^^^^^^^^^^^^^^^^^^^^^^
  File "C:\Users\luis.vieira\AppData\Local\Programs\Python\Python312\Lib\site-packages\flask_limiter\extension.py", line 1299, in __inner
    self.limiter._check_request_limit(
  File "C:\Users\luis.vieira\AppData\Local\Programs\Python\Python312\Lib\site-packages\flask_limiter\extension.py", line 1160, in _check_request_limit
    raise e
  File "C:\Users\luis.vieira\AppData\Local\Programs\Python\Python312\Lib\site-packages\flask_limiter\extension.py", line 1157, in _check_request_limit
    self.__evaluate_limits(endpoint, all_limits)
  File "C:\Users\luis.vieira\AppData\Local\Programs\Python\Python312\Lib\site-packages\flask_limiter\extension.py", line 1141, in __evaluate_limits
    raise RateLimitExceeded(
flask_limiter.errors.RateLimitExceeded: 429 Too Many Requests: 5 per 1 minute

2024-11-06 11:22:09,255 INFO [extension:1095] ratelimit 5 per 1 minute (127.0.0.1) exceeded at endpoint: login
2024-11-06 11:22:09,256 ERROR [app:373] Server Error: Traceback (most recent call last):
  File "C:\Users\luis.vieira\AppData\Local\Programs\Python\Python312\Lib\site-packages\flask\app.py", line 880, in full_dispatch_request
    rv = self.dispatch_request()
         ^^^^^^^^^^^^^^^^^^^^^^^
  File "C:\Users\luis.vieira\AppData\Local\Programs\Python\Python312\Lib\site-packages\flask\app.py", line 865, in dispatch_request
    return self.ensure_sync(self.view_functions[rule.endpoint])(**view_args)  # type: ignore[no-any-return]
           ^^^^^^^^^^^^^^^^^^^^^^^^^^^^^^^^^^^^^^^^^^^^^^^^^^^^^^^^^^^^^^^^^
  File "C:\Users\luis.vieira\AppData\Local\Programs\Python\Python312\Lib\site-packages\flask_limiter\extension.py", line 1299, in __inner
    self.limiter._check_request_limit(
  File "C:\Users\luis.vieira\AppData\Local\Programs\Python\Python312\Lib\site-packages\flask_limiter\extension.py", line 1160, in _check_request_limit
    raise e
  File "C:\Users\luis.vieira\AppData\Local\Programs\Python\Python312\Lib\site-packages\flask_limiter\extension.py", line 1157, in _check_request_limit
    self.__evaluate_limits(endpoint, all_limits)
  File "C:\Users\luis.vieira\AppData\Local\Programs\Python\Python312\Lib\site-packages\flask_limiter\extension.py", line 1141, in __evaluate_limits
    raise RateLimitExceeded(
flask_limiter.errors.RateLimitExceeded: 429 Too Many Requests: 5 per 1 minute

2024-11-06 11:22:11,676 INFO [extension:1095] ratelimit 5 per 1 minute (127.0.0.1) exceeded at endpoint: login
2024-11-06 11:22:11,678 ERROR [app:373] Server Error: Traceback (most recent call last):
  File "C:\Users\luis.vieira\AppData\Local\Programs\Python\Python312\Lib\site-packages\flask\app.py", line 880, in full_dispatch_request
    rv = self.dispatch_request()
         ^^^^^^^^^^^^^^^^^^^^^^^
  File "C:\Users\luis.vieira\AppData\Local\Programs\Python\Python312\Lib\site-packages\flask\app.py", line 865, in dispatch_request
    return self.ensure_sync(self.view_functions[rule.endpoint])(**view_args)  # type: ignore[no-any-return]
           ^^^^^^^^^^^^^^^^^^^^^^^^^^^^^^^^^^^^^^^^^^^^^^^^^^^^^^^^^^^^^^^^^
  File "C:\Users\luis.vieira\AppData\Local\Programs\Python\Python312\Lib\site-packages\flask_limiter\extension.py", line 1299, in __inner
    self.limiter._check_request_limit(
  File "C:\Users\luis.vieira\AppData\Local\Programs\Python\Python312\Lib\site-packages\flask_limiter\extension.py", line 1160, in _check_request_limit
    raise e
  File "C:\Users\luis.vieira\AppData\Local\Programs\Python\Python312\Lib\site-packages\flask_limiter\extension.py", line 1157, in _check_request_limit
    self.__evaluate_limits(endpoint, all_limits)
  File "C:\Users\luis.vieira\AppData\Local\Programs\Python\Python312\Lib\site-packages\flask_limiter\extension.py", line 1141, in __evaluate_limits
    raise RateLimitExceeded(
flask_limiter.errors.RateLimitExceeded: 429 Too Many Requests: 5 per 1 minute

2024-11-06 11:22:15,973 INFO [wasyncore:485] Serving on http://0.0.0.0:8279
2024-11-06 11:22:22,236 INFO [app:128] Tentativa de login do usuario: luis
2024-11-06 11:22:22,600 INFO [app:175] usuario luis logado com sucesso.
2024-11-06 11:22:22,622 INFO [app:93] usuario 2 carregado com sucesso.
2024-11-06 11:22:25,088 INFO [app:93] usuario 2 carregado com sucesso.
2024-11-06 11:24:53,139 INFO [wasyncore:485] Serving on http://0.0.0.0:8279
2024-11-06 11:25:04,539 INFO [app:93] usuario 2 carregado com sucesso.
2024-11-06 11:25:23,165 INFO [app:93] usuario 2 carregado com sucesso.
2024-11-06 11:25:23,687 WARNING [app:378] Página não encontrada: http://localhost:8279/favicon.ico
2024-11-06 11:25:23,708 INFO [app:93] usuario 2 carregado com sucesso.
2024-11-06 11:25:25,647 INFO [app:93] usuario 2 carregado com sucesso.
2024-11-06 11:25:25,647 INFO [app:190] usuario 2 fez logout.
2024-11-06 11:25:30,051 INFO [app:128] Tentativa de login do usuario: luis
2024-11-06 11:25:30,401 INFO [app:175] usuario luis logado com sucesso.
2024-11-06 11:25:30,430 INFO [app:93] usuario 2 carregado com sucesso.
2024-11-06 11:25:31,630 INFO [app:93] usuario 2 carregado com sucesso.
2024-11-06 11:35:37,899 INFO [csrf:263] The CSRF session token is missing.
2024-11-06 11:35:37,900 INFO [app:365] Um usuário não autenticado foi deslogado por inatividade
2024-11-06 11:41:29,148 INFO [app:128] Tentativa de login do usuario: luis
2024-11-06 11:41:29,526 INFO [app:175] usuario luis logado com sucesso.
2024-11-06 11:41:29,550 INFO [app:93] usuario 2 carregado com sucesso.
2024-11-06 11:41:30,482 INFO [app:93] usuario 2 carregado com sucesso.
2024-11-06 11:44:43,622 INFO [wasyncore:485] Serving on http://0.0.0.0:8279
2024-11-06 11:44:54,290 INFO [app:93] usuario 2 carregado com sucesso.
2024-11-06 12:50:39,283 INFO [csrf:263] The CSRF session token is missing.
2024-11-06 12:50:39,287 INFO [app:365] Um usuário não autenticado foi deslogado por inatividade
2024-11-06 12:50:39,586 INFO [csrf:263] The CSRF session token is missing.
2024-11-06 12:50:39,587 INFO [app:365] Um usuário não autenticado foi deslogado por inatividade
2024-11-06 12:57:09,107 INFO [wasyncore:485] Serving on http://0.0.0.0:8279
2024-11-06 12:57:18,863 INFO [app:128] Tentativa de login do usuario: luis
2024-11-06 12:57:19,304 INFO [app:175] usuario luis logado com sucesso.
2024-11-06 12:57:19,329 INFO [app:93] usuario 2 carregado com sucesso.
2024-11-06 12:57:20,483 INFO [app:93] usuario 2 carregado com sucesso.
2024-11-06 12:58:55,733 INFO [wasyncore:485] Serving on http://0.0.0.0:8279
2024-11-06 12:58:57,480 INFO [app:93] usuario 2 carregado com sucesso.
2024-11-06 13:00:16,423 INFO [wasyncore:485] Serving on http://0.0.0.0:8279
2024-11-06 13:00:20,701 INFO [app:93] usuario 2 carregado com sucesso.
2024-11-06 13:01:14,508 INFO [wasyncore:485] Serving on http://0.0.0.0:8279
2024-11-06 13:01:20,120 INFO [app:93] usuario 2 carregado com sucesso.
2024-11-06 13:01:21,244 INFO [app:93] usuario 2 carregado com sucesso.
2024-11-06 13:01:22,031 WARNING [app:378] Página não encontrada: http://localhost:8279/favicon.ico
2024-11-06 13:01:22,053 INFO [app:93] usuario 2 carregado com sucesso.
2024-11-06 13:23:28,278 INFO [csrf:263] The CSRF session token is missing.
2024-11-06 13:23:28,287 INFO [app:365] Um usuário não autenticado foi deslogado por inatividade
2024-11-06 13:27:48,168 INFO [app:128] Tentativa de login do usuario: luis
2024-11-06 13:27:48,571 INFO [app:175] usuario luis logado com sucesso.
2024-11-06 13:27:48,600 INFO [app:93] usuario 2 carregado com sucesso.
2024-11-06 13:27:50,415 INFO [app:93] usuario 2 carregado com sucesso.
2024-11-06 13:27:52,989 INFO [app:93] usuario 2 carregado com sucesso.
2024-11-06 13:37:59,106 INFO [csrf:263] The CSRF session token is missing.
2024-11-06 13:37:59,106 INFO [app:365] Um usuário não autenticado foi deslogado por inatividade
2024-11-06 13:56:05,980 INFO [wasyncore:485] Serving on http://0.0.0.0:8279
2024-11-06 13:58:21,738 INFO [csrf:263] The CSRF session token is missing.
2024-11-06 13:58:21,740 INFO [app:365] Um usuário não autenticado foi deslogado por inatividade
2024-11-06 13:58:27,527 INFO [app:128] Tentativa de login do usuario: luis
2024-11-06 13:58:27,999 INFO [app:175] usuario luis logado com sucesso.
2024-11-06 13:58:28,023 INFO [app:93] usuario 2 carregado com sucesso.
2024-11-06 13:58:29,753 INFO [app:93] usuario 2 carregado com sucesso.
2024-11-06 14:14:27,009 INFO [csrf:263] The CSRF session token is missing.
2024-11-06 14:14:27,023 INFO [app:365] Um usuário não autenticado foi deslogado por inatividade
2024-11-06 14:14:27,059 INFO [csrf:263] The CSRF session token is missing.
2024-11-06 14:14:27,059 INFO [app:365] Um usuário não autenticado foi deslogado por inatividade
2024-11-06 14:22:23,694 INFO [wasyncore:485] Serving on http://0.0.0.0:8279
2024-11-06 16:40:00,922 INFO [app:128] Tentativa de login do usuario: luis
2024-11-06 16:40:01,455 INFO [app:175] usuario luis logado com sucesso.
2024-11-06 16:40:01,484 INFO [app:93] usuario 2 carregado com sucesso.
2024-11-06 16:40:04,270 INFO [app:93] usuario 2 carregado com sucesso.
2024-11-06 16:48:42,610 INFO [wasyncore:485] Serving on http://0.0.0.0:8279
2024-11-06 16:48:45,538 INFO [app:93] usuario 2 carregado com sucesso.
2024-11-06 16:48:45,976 WARNING [app:378] Página não encontrada: http://localhost:8279/favicon.ico
2024-11-06 16:48:46,000 INFO [app:93] usuario 2 carregado com sucesso.
2024-11-06 16:48:50,583 INFO [app:128] Tentativa de login do usuario: luis
2024-11-06 16:48:50,950 INFO [app:175] usuario luis logado com sucesso.
2024-11-06 16:48:50,976 INFO [app:93] usuario 2 carregado com sucesso.
2024-11-06 16:48:57,552 INFO [app:93] usuario 2 carregado com sucesso.
2024-11-06 16:49:39,898 INFO [wasyncore:485] Serving on http://0.0.0.0:8279
2024-11-06 16:49:41,919 INFO [app:93] usuario 2 carregado com sucesso.
2024-11-06 16:50:11,252 INFO [app:93] usuario 2 carregado com sucesso.
2024-11-06 16:50:11,252 INFO [app:190] usuario 2 fez logout.
2024-11-06 16:51:04,993 INFO [wasyncore:485] Serving on http://0.0.0.0:8279
2024-11-06 16:51:17,939 INFO [app:128] Tentativa de login do usuario: luis
2024-11-06 16:51:18,356 INFO [app:175] usuario luis logado com sucesso.
2024-11-06 16:51:18,384 INFO [app:93] usuario 2 carregado com sucesso.
2024-11-06 16:51:19,281 INFO [app:93] usuario 2 carregado com sucesso.
2024-11-06 16:57:27,237 INFO [wasyncore:485] Serving on http://0.0.0.0:8279
2024-11-06 16:57:32,001 INFO [app:93] usuario 2 carregado com sucesso.
2024-11-06 17:12:33,239 INFO [csrf:263] The CSRF session token is missing.
2024-11-06 17:12:33,242 INFO [app:365] Um usuário não autenticado foi deslogado por inatividade
2024-11-06 17:14:23,617 INFO [wasyncore:485] Serving on http://0.0.0.0:8279
2024-11-06 17:14:28,632 INFO [app:128] Tentativa de login do usuario: luis
2024-11-06 17:14:29,153 INFO [app:175] usuario luis logado com sucesso.
2024-11-06 17:14:29,180 INFO [app:93] usuario 2 carregado com sucesso.
2024-11-06 17:14:30,871 INFO [app:93] usuario 2 carregado com sucesso.
2024-11-06 17:16:49,996 INFO [app:93] usuario 2 carregado com sucesso.
2024-11-06 17:16:49,997 INFO [app:190] usuario 2 fez logout.
2024-11-06 17:17:01,667 INFO [app:128] Tentativa de login do usuario: luis
2024-11-06 17:17:02,123 INFO [app:175] usuario luis logado com sucesso.
2024-11-06 17:17:02,414 INFO [app:93] usuario 2 carregado com sucesso.
2024-11-06 17:17:07,623 INFO [app:93] usuario 2 carregado com sucesso.
2024-11-06 17:17:11,770 WARNING [app:378] Página não encontrada: http://localhost:8279/logs
2024-11-06 17:17:11,792 INFO [app:93] usuario 2 carregado com sucesso.
2024-11-06 17:17:17,503 INFO [app:93] usuario 2 carregado com sucesso.
2024-11-06 17:17:45,081 INFO [app:93] usuario 2 carregado com sucesso.
2024-11-06 17:20:22,791 INFO [wasyncore:485] Serving on http://0.0.0.0:8279
2024-11-06 17:20:24,079 INFO [app:93] usuario 2 carregado com sucesso.
2024-11-06 17:24:39,546 INFO [app:93] usuario 2 carregado com sucesso.
2024-11-06 17:27:36,838 INFO [wasyncore:485] Serving on http://0.0.0.0:8279
2024-11-06 17:27:42,361 INFO [app:93] usuario 2 carregado com sucesso.
2024-11-06 17:27:46,642 INFO [app:128] Tentativa de login do usuario: luis
2024-11-06 17:27:47,017 INFO [app:175] usuario luis logado com sucesso.
2024-11-06 17:27:47,049 INFO [app:93] usuario 2 carregado com sucesso.
2024-11-06 17:27:48,572 INFO [app:93] usuario 2 carregado com sucesso.
2024-11-06 22:50:48,920 INFO [wasyncore:485] Serving on http://0.0.0.0:8279
2024-11-06 22:50:56,203 WARNING [app:383] Página não encontrada: http://localhost:8279/favicon.ico
2024-11-06 22:51:00,476 WARNING [app:383] Página não encontrada: http://localhost:8279/favicon.ico
2024-11-06 22:51:04,969 INFO [app:129] Tentativa de login do usuario: luis
2024-11-06 22:51:05,489 INFO [app:176] usuario luis logado com sucesso.
2024-11-06 22:51:05,573 INFO [app:94] usuario 2 carregado com sucesso.
2024-11-06 22:51:23,992 INFO [app:94] usuario 2 carregado com sucesso.
2024-11-06 22:51:23,992 INFO [app:195] usuario 2 fez logout.
2024-11-06 22:53:07,462 INFO [wasyncore:485] Serving on http://0.0.0.0:8279
2024-11-06 22:53:34,399 INFO [app:129] Tentativa de login do usuario: luis
2024-11-06 22:53:34,865 INFO [app:176] usuario luis logado com sucesso.
2024-11-06 22:53:34,948 INFO [app:94] usuario 2 carregado com sucesso.
2024-11-06 22:53:37,480 INFO [app:94] usuario 2 carregado com sucesso.
2024-11-06 22:53:37,481 INFO [app:195] usuario 2 fez logout.
2024-11-06 22:54:30,107 INFO [wasyncore:485] Serving on http://0.0.0.0:8279
2024-11-06 22:54:34,718 INFO [app:129] Tentativa de login do usuario: luis
2024-11-06 22:54:35,178 INFO [app:176] usuario luis logado com sucesso.
2024-11-06 22:54:35,260 INFO [app:94] usuario 2 carregado com sucesso.
2024-11-06 22:54:37,852 INFO [app:94] usuario 2 carregado com sucesso.
2024-11-06 22:54:37,852 INFO [app:195] usuario 2 fez logout.
2024-11-06 22:55:40,062 INFO [app:129] Tentativa de login do usuario: luis
2024-11-06 22:55:40,505 INFO [app:176] usuario luis logado com sucesso.
2024-11-06 22:55:40,583 INFO [app:94] usuario 2 carregado com sucesso.
2024-11-06 22:55:42,025 INFO [app:94] usuario 2 carregado com sucesso.
2024-11-06 22:55:44,473 INFO [app:94] usuario 2 carregado com sucesso.
2024-11-06 22:55:44,473 INFO [app:195] usuario 2 fez logout.
2024-11-06 23:00:11,671 INFO [wasyncore:485] Serving on http://0.0.0.0:8279
2024-11-06 23:00:18,407 INFO [app:129] Tentativa de login do usuario: luis
2024-11-06 23:00:18,884 INFO [app:176] usuario luis logado com sucesso.
2024-11-06 23:00:19,017 INFO [app:94] usuario 2 carregado com sucesso.
2024-11-06 23:00:25,088 INFO [app:94] usuario 2 carregado com sucesso.
2024-11-06 23:05:43,669 INFO [wasyncore:485] Serving on http://0.0.0.0:8279
2024-11-06 23:06:04,018 INFO [app:94] usuario 2 carregado com sucesso.
2024-11-06 23:07:28,968 INFO [app:94] usuario 2 carregado com sucesso.
2024-11-06 23:07:28,968 INFO [app:195] usuario 2 fez logout.
2024-11-06 23:07:46,174 INFO [app:129] Tentativa de login do usuario: felipe
2024-11-06 23:07:46,526 ERROR [app:378] Server Error: Traceback (most recent call last):
  File "C:\Users\luism\AppData\Local\Programs\Python\Python312\Lib\site-packages\flask\app.py", line 880, in full_dispatch_request
    rv = self.dispatch_request()
         ^^^^^^^^^^^^^^^^^^^^^^^
  File "C:\Users\luism\AppData\Local\Programs\Python\Python312\Lib\site-packages\flask\app.py", line 865, in dispatch_request
    return self.ensure_sync(self.view_functions[rule.endpoint])(**view_args)  # type: ignore[no-any-return]
           ^^^^^^^^^^^^^^^^^^^^^^^^^^^^^^^^^^^^^^^^^^^^^^^^^^^^^^^^^^^^^^^^^
  File "C:\Users\luism\AppData\Local\Programs\Python\Python312\Lib\site-packages\flask_limiter\extension.py", line 1303, in __inner
    return cast(R, flask.current_app.ensure_sync(obj)(*a, **k))
                   ^^^^^^^^^^^^^^^^^^^^^^^^^^^^^^^^^^^^^^^^^^^
  File "C:\Users\luism\OneDrive\Documents\GitHub\Flask4\app.py", line 151, in login
    if not stored_password.startswith('$2b$'):
           ^^^^^^^^^^^^^^^^^^^^^^^^^^
AttributeError: 'NoneType' object has no attribute 'startswith'

2024-11-06 23:07:57,818 WARNING [app:383] Página não encontrada: http://localhost:8279/favicon.ico
2024-11-06 23:08:09,372 INFO [app:129] Tentativa de login do usuario: felipe
2024-11-06 23:08:09,877 INFO [app:161] Senha do usuario felipe atualizada para hash bcrypt.
2024-11-06 23:08:10,242 INFO [app:176] usuario felipe logado com sucesso.
2024-11-06 23:08:10,354 INFO [app:94] usuario 5 carregado com sucesso.
2024-11-06 23:08:13,246 INFO [app:94] usuario 5 carregado com sucesso.
2024-11-06 23:08:29,763 INFO [app:94] usuario 5 carregado com sucesso.
2024-11-06 23:08:29,763 INFO [app:195] usuario 5 fez logout.
2024-11-06 23:09:45,515 INFO [app:129] Tentativa de login do usuario: rafaele
2024-11-06 23:09:46,034 INFO [app:161] Senha do usuario rafaele atualizada para hash bcrypt.
2024-11-06 23:09:46,396 INFO [app:176] usuario rafaele logado com sucesso.
2024-11-06 23:09:46,481 INFO [app:94] usuario 6 carregado com sucesso.
2024-11-06 23:09:48,067 INFO [app:94] usuario 6 carregado com sucesso.
2024-11-06 23:11:28,988 INFO [app:94] usuario 6 carregado com sucesso.
2024-11-06 23:11:28,988 INFO [app:195] usuario 6 fez logout.
2024-11-06 23:11:35,691 INFO [app:129] Tentativa de login do usuario: jockey
2024-11-06 23:11:36,151 INFO [app:176] usuario jockey logado com sucesso.
2024-11-06 23:11:36,261 INFO [app:94] usuario 3 carregado com sucesso.
2024-11-06 23:11:37,983 INFO [app:94] usuario 3 carregado com sucesso.
2024-11-06 23:11:44,207 INFO [app:94] usuario 3 carregado com sucesso.
2024-11-06 23:11:44,207 INFO [app:195] usuario 3 fez logout.
2024-11-06 23:12:25,640 INFO [app:129] Tentativa de login do usuario: jockey
2024-11-06 23:12:26,084 INFO [app:176] usuario jockey logado com sucesso.
2024-11-06 23:12:26,163 INFO [app:94] usuario 3 carregado com sucesso.
2024-11-06 23:12:30,153 INFO [app:94] usuario 3 carregado com sucesso.
2024-11-06 23:12:30,153 INFO [app:195] usuario 3 fez logout.
2024-11-06 23:12:35,356 INFO [app:129] Tentativa de login do usuario: jockey
2024-11-06 23:12:35,845 INFO [app:176] usuario jockey logado com sucesso.
2024-11-06 23:12:35,929 INFO [app:94] usuario 3 carregado com sucesso.
2024-11-06 23:12:37,725 INFO [app:94] usuario 3 carregado com sucesso.
2024-11-06 23:12:45,937 INFO [app:94] usuario 3 carregado com sucesso.
2024-11-06 23:12:45,937 INFO [app:195] usuario 3 fez logout.
2024-11-06 23:12:51,353 INFO [app:129] Tentativa de login do usuario: felipe
2024-11-06 23:12:51,813 INFO [app:176] usuario felipe logado com sucesso.
2024-11-06 23:12:51,895 INFO [app:94] usuario 5 carregado com sucesso.
2024-11-06 23:12:55,880 INFO [app:94] usuario 5 carregado com sucesso.
2024-11-06 23:15:00,403 INFO [app:94] usuario 5 carregado com sucesso.
2024-11-06 23:15:00,405 INFO [app:195] usuario 5 fez logout.
2024-11-06 23:15:21,937 INFO [app:129] Tentativa de login do usuario: felipe
2024-11-06 23:15:22,368 INFO [app:176] usuario felipe logado com sucesso.
2024-11-06 23:15:22,451 INFO [app:94] usuario 5 carregado com sucesso.
2024-11-06 23:15:24,055 INFO [app:94] usuario 5 carregado com sucesso.
2024-11-06 23:17:02,395 INFO [wasyncore:485] Serving on http://0.0.0.0:8279
2024-11-06 23:17:05,557 INFO [app:94] usuario 5 carregado com sucesso.
2024-11-06 23:17:08,052 INFO [app:94] usuario 5 carregado com sucesso.
2024-11-06 23:17:13,378 INFO [app:94] usuario 5 carregado com sucesso.
2024-11-06 23:17:13,378 INFO [app:195] usuario 5 fez logout.
2024-11-06 23:17:20,075 INFO [app:129] Tentativa de login do usuario: felipe
2024-11-06 23:17:20,520 INFO [app:176] usuario felipe logado com sucesso.
2024-11-06 23:17:20,598 INFO [app:94] usuario 5 carregado com sucesso.
2024-11-06 23:17:22,045 INFO [app:94] usuario 5 carregado com sucesso.
2024-11-06 23:26:56,942 INFO [wasyncore:485] Serving on http://0.0.0.0:8279
2024-11-06 23:27:04,158 INFO [app:94] usuario 5 carregado com sucesso.
2024-11-06 23:27:09,373 INFO [app:94] usuario 5 carregado com sucesso.
2024-11-06 23:27:09,373 INFO [app:195] usuario 5 fez logout.
2024-11-06 23:27:15,080 INFO [app:129] Tentativa de login do usuario: felipe
2024-11-06 23:27:15,532 INFO [app:176] usuario felipe logado com sucesso.
2024-11-06 23:27:15,616 INFO [app:94] usuario 5 carregado com sucesso.
2024-11-06 23:27:16,931 INFO [app:94] usuario 5 carregado com sucesso.
2024-11-06 23:29:13,962 INFO [wasyncore:485] Serving on http://0.0.0.0:8279
2024-11-06 23:29:17,369 INFO [app:94] usuario 5 carregado com sucesso.
2024-11-06 23:29:35,500 INFO [wasyncore:485] Serving on http://0.0.0.0:8279
2024-11-06 23:29:37,765 INFO [app:94] usuario 5 carregado com sucesso.
2024-11-07 12:58:05,080 INFO [wasyncore:485] Serving on http://0.0.0.0:8279
2024-11-07 12:58:05,787 WARNING [app:383] Página não encontrada: http://localhost:8279/favicon.ico
2024-11-07 12:58:09,738 INFO [app:129] Tentativa de login do usuario: luis
2024-11-07 12:58:10,209 INFO [app:176] usuario luis logado com sucesso.
2024-11-07 12:58:10,232 INFO [app:94] usuario 1 carregado com sucesso.
2024-11-07 12:58:11,858 INFO [app:94] usuario 1 carregado com sucesso.
2024-11-07 12:58:17,317 INFO [app:94] usuario 1 carregado com sucesso.
2024-11-07 12:58:17,317 INFO [app:195] usuario 1 fez logout.
2024-11-07 12:58:21,898 INFO [app:129] Tentativa de login do usuario: luis
2024-11-07 12:58:22,261 WARNING [app:179] Tentativa de login falhou para luis: senha inválida.
2024-11-07 12:58:33,050 INFO [app:129] Tentativa de login do usuario: luis
2024-11-07 12:58:33,381 WARNING [app:179] Tentativa de login falhou para luis: senha inválida.
2024-11-07 12:58:33,497 WARNING [app:383] Página não encontrada: http://localhost:8279/favicon.ico
2024-11-07 12:58:38,022 INFO [extension:1095] ratelimit 5 per 1 minute (127.0.0.1) exceeded at endpoint: login
2024-11-07 12:58:38,026 ERROR [app:378] Server Error: Traceback (most recent call last):
  File "C:\Users\luis.vieira\AppData\Local\Programs\Python\Python312\Lib\site-packages\flask\app.py", line 880, in full_dispatch_request
    rv = self.dispatch_request()
         ^^^^^^^^^^^^^^^^^^^^^^^
  File "C:\Users\luis.vieira\AppData\Local\Programs\Python\Python312\Lib\site-packages\flask\app.py", line 865, in dispatch_request
    return self.ensure_sync(self.view_functions[rule.endpoint])(**view_args)  # type: ignore[no-any-return]
           ^^^^^^^^^^^^^^^^^^^^^^^^^^^^^^^^^^^^^^^^^^^^^^^^^^^^^^^^^^^^^^^^^
  File "C:\Users\luis.vieira\AppData\Local\Programs\Python\Python312\Lib\site-packages\flask_limiter\extension.py", line 1299, in __inner
    self.limiter._check_request_limit(
  File "C:\Users\luis.vieira\AppData\Local\Programs\Python\Python312\Lib\site-packages\flask_limiter\extension.py", line 1160, in _check_request_limit
    raise e
  File "C:\Users\luis.vieira\AppData\Local\Programs\Python\Python312\Lib\site-packages\flask_limiter\extension.py", line 1157, in _check_request_limit
    self.__evaluate_limits(endpoint, all_limits)
  File "C:\Users\luis.vieira\AppData\Local\Programs\Python\Python312\Lib\site-packages\flask_limiter\extension.py", line 1141, in __evaluate_limits
    raise RateLimitExceeded(
flask_limiter.errors.RateLimitExceeded: 429 Too Many Requests: 5 per 1 minute

2024-11-07 12:58:42,822 INFO [extension:1095] ratelimit 5 per 1 minute (127.0.0.1) exceeded at endpoint: login
2024-11-07 12:58:42,825 ERROR [app:378] Server Error: Traceback (most recent call last):
  File "C:\Users\luis.vieira\AppData\Local\Programs\Python\Python312\Lib\site-packages\flask\app.py", line 880, in full_dispatch_request
    rv = self.dispatch_request()
         ^^^^^^^^^^^^^^^^^^^^^^^
  File "C:\Users\luis.vieira\AppData\Local\Programs\Python\Python312\Lib\site-packages\flask\app.py", line 865, in dispatch_request
    return self.ensure_sync(self.view_functions[rule.endpoint])(**view_args)  # type: ignore[no-any-return]
           ^^^^^^^^^^^^^^^^^^^^^^^^^^^^^^^^^^^^^^^^^^^^^^^^^^^^^^^^^^^^^^^^^
  File "C:\Users\luis.vieira\AppData\Local\Programs\Python\Python312\Lib\site-packages\flask_limiter\extension.py", line 1299, in __inner
    self.limiter._check_request_limit(
  File "C:\Users\luis.vieira\AppData\Local\Programs\Python\Python312\Lib\site-packages\flask_limiter\extension.py", line 1160, in _check_request_limit
    raise e
  File "C:\Users\luis.vieira\AppData\Local\Programs\Python\Python312\Lib\site-packages\flask_limiter\extension.py", line 1157, in _check_request_limit
    self.__evaluate_limits(endpoint, all_limits)
  File "C:\Users\luis.vieira\AppData\Local\Programs\Python\Python312\Lib\site-packages\flask_limiter\extension.py", line 1141, in __evaluate_limits
    raise RateLimitExceeded(
flask_limiter.errors.RateLimitExceeded: 429 Too Many Requests: 5 per 1 minute

2024-11-07 13:00:06,658 INFO [wasyncore:485] Serving on http://0.0.0.0:8279
2024-11-07 13:00:15,411 WARNING [app:383] Página não encontrada: http://localhost:8279/favicon.ico
2024-11-07 13:00:18,801 INFO [app:129] Tentativa de login do usuario: luis
2024-11-07 13:00:19,200 WARNING [app:179] Tentativa de login falhou para luis: senha inválida.
2024-11-07 13:00:25,903 INFO [app:129] Tentativa de login do usuario: luis
2024-11-07 13:00:26,249 WARNING [app:179] Tentativa de login falhou para luis: senha inválida.
2024-11-07 13:00:26,365 WARNING [app:383] Página não encontrada: http://localhost:8279/favicon.ico
2024-11-07 13:00:31,655 INFO [app:129] Tentativa de login do usuario: luis
2024-11-07 13:00:32,003 INFO [app:176] usuario luis logado com sucesso.
2024-11-07 13:00:32,028 INFO [app:94] usuario 1 carregado com sucesso.
2024-11-07 13:00:33,781 INFO [app:94] usuario 1 carregado com sucesso.
2024-11-07 13:10:40,302 INFO [csrf:263] The CSRF session token is missing.
2024-11-07 13:10:40,302 INFO [app:370] Um usuário não autenticado foi deslogado por inatividade
2024-11-07 14:30:15,058 INFO [wasyncore:485] Serving on http://0.0.0.0:8279
2024-11-07 14:30:20,917 INFO [app:129] Tentativa de login do usuario: luis
2024-11-07 14:30:21,451 INFO [app:176] usuario luis logado com sucesso.
2024-11-07 14:30:21,478 INFO [app:94] usuario 1 carregado com sucesso.
2024-11-07 14:30:23,319 INFO [app:94] usuario 1 carregado com sucesso.
2024-11-07 14:32:12,269 INFO [wasyncore:485] Serving on http://0.0.0.0:8279
2024-11-07 14:32:20,524 INFO [app:94] usuario 1 carregado com sucesso.
2024-11-07 14:32:23,085 INFO [app:94] usuario 1 carregado com sucesso.
2024-11-07 14:32:23,745 WARNING [app:383] Página não encontrada: http://localhost:8279/favicon.ico
2024-11-07 14:32:23,769 INFO [app:94] usuario 1 carregado com sucesso.
2024-11-07 14:34:53,398 INFO [wasyncore:485] Serving on http://0.0.0.0:8279
2024-11-07 14:34:56,763 INFO [app:94] usuario 1 carregado com sucesso.
2024-11-07 14:38:30,434 INFO [app:94] usuario 1 carregado com sucesso.
2024-11-07 14:38:44,624 INFO [wasyncore:485] Serving on http://0.0.0.0:8279
2024-11-07 14:38:47,007 INFO [app:94] usuario 1 carregado com sucesso.
2024-11-07 14:38:49,777 INFO [app:94] usuario 1 carregado com sucesso.
2024-11-07 14:38:50,334 WARNING [app:383] Página não encontrada: http://localhost:8279/favicon.ico
2024-11-07 14:38:50,355 INFO [app:94] usuario 1 carregado com sucesso.
2024-11-07 14:38:50,921 INFO [app:94] usuario 1 carregado com sucesso.
2024-11-07 14:38:51,351 WARNING [app:383] Página não encontrada: http://localhost:8279/favicon.ico
2024-11-07 14:38:51,369 INFO [app:94] usuario 1 carregado com sucesso.
2024-11-07 14:38:51,770 INFO [app:94] usuario 1 carregado com sucesso.
2024-11-07 14:38:52,187 WARNING [app:383] Página não encontrada: http://localhost:8279/favicon.ico
2024-11-07 14:38:52,209 INFO [app:94] usuario 1 carregado com sucesso.
2024-11-07 14:39:37,525 INFO [wasyncore:485] Serving on http://0.0.0.0:8279
2024-11-07 14:39:40,139 INFO [app:94] usuario 1 carregado com sucesso.
2024-11-07 14:50:50,120 INFO [app:129] Tentativa de login do usuario: luis
2024-11-07 14:50:50,482 INFO [app:176] usuario luis logado com sucesso.
2024-11-07 14:50:50,525 INFO [app:94] usuario 1 carregado com sucesso.
2024-11-07 14:50:51,803 INFO [app:94] usuario 1 carregado com sucesso.
2024-11-07 15:11:02,585 INFO [csrf:263] The CSRF session token is missing.
2024-11-07 15:11:02,586 INFO [app:370] Um usuário não autenticado foi deslogado por inatividade
2024-11-07 15:19:22,169 INFO [app:129] Tentativa de login do usuario: luis
2024-11-07 15:19:22,570 INFO [app:176] usuario luis logado com sucesso.
2024-11-07 15:19:22,595 INFO [app:94] usuario 1 carregado com sucesso.
2024-11-07 15:19:23,896 INFO [app:94] usuario 1 carregado com sucesso.
2024-11-07 15:22:32,809 INFO [app:94] usuario 1 carregado com sucesso.
2024-11-07 15:22:32,809 INFO [app:195] usuario 1 fez logout.
2024-11-07 15:22:41,808 INFO [app:129] Tentativa de login do usuario: Dyhonatan
2024-11-07 15:22:42,198 INFO [app:161] Senha do usuario Dyhonatan atualizada para hash bcrypt.
2024-11-07 15:22:42,513 INFO [app:176] usuario Dyhonatan logado com sucesso.
2024-11-07 15:22:42,540 INFO [app:94] usuario 183 carregado com sucesso.
2024-11-07 15:22:46,534 INFO [app:94] usuario 183 carregado com sucesso.
2024-11-07 15:34:54,535 INFO [csrf:263] The CSRF session token is missing.
2024-11-07 15:34:54,535 INFO [app:370] Um usuário não autenticado foi deslogado por inatividade
2024-11-07 16:29:40,464 INFO [csrf:263] The CSRF session token is missing.
2024-11-07 16:29:40,466 INFO [app:370] Um usuário não autenticado foi deslogado por inatividade
2024-11-07 16:29:45,270 INFO [app:129] Tentativa de login do usuario: luis
2024-11-07 16:29:45,657 INFO [app:176] usuario luis logado com sucesso.
2024-11-07 16:29:45,684 INFO [app:94] usuario 1 carregado com sucesso.
2024-11-07 16:29:46,772 INFO [app:94] usuario 1 carregado com sucesso.
2024-11-07 16:30:03,579 INFO [app:94] usuario 1 carregado com sucesso.
2024-11-07 16:30:03,580 INFO [app:195] usuario 1 fez logout.
2024-11-07 16:30:26,094 INFO [app:129] Tentativa de login do usuario: Duin
2024-11-07 16:30:26,465 INFO [app:161] Senha do usuario Duin atualizada para hash bcrypt.
2024-11-07 16:30:26,784 INFO [app:176] usuario Duin logado com sucesso.
2024-11-07 16:30:26,808 INFO [app:94] usuario 192 carregado com sucesso.
2024-11-07 16:30:28,766 INFO [app:94] usuario 192 carregado com sucesso.
2024-11-07 16:31:31,048 INFO [app:94] usuario 192 carregado com sucesso.
2024-11-07 16:32:49,138 INFO [wasyncore:485] Serving on http://0.0.0.0:8279
2024-11-07 16:32:50,541 INFO [app:94] usuario 192 carregado com sucesso.
2024-11-07 16:49:14,928 INFO [csrf:263] The CSRF session token is missing.
2024-11-07 16:49:14,931 INFO [app:370] Um usuário não autenticado foi deslogado por inatividade
2024-11-07 16:51:39,178 INFO [app:129] Tentativa de login do usuario: felipe
2024-11-07 16:51:39,625 INFO [app:161] Senha do usuario felipe atualizada para hash bcrypt.
2024-11-07 16:51:39,930 INFO [app:176] usuario felipe logado com sucesso.
2024-11-07 16:51:39,958 INFO [app:94] usuario 210 carregado com sucesso.
2024-11-07 16:51:41,224 INFO [app:94] usuario 210 carregado com sucesso.
2024-11-07 16:52:08,228 INFO [app:94] usuario 210 carregado com sucesso.
2024-11-07 16:52:08,228 INFO [app:195] usuario 210 fez logout.
2024-11-07 16:54:29,937 INFO [app:129] Tentativa de login do usuario: Palladium
2024-11-07 16:54:30,314 INFO [app:161] Senha do usuario Palladium atualizada para hash bcrypt.
2024-11-07 16:54:30,631 INFO [app:176] usuario Palladium logado com sucesso.
2024-11-07 16:54:30,655 INFO [app:94] usuario 154 carregado com sucesso.
2024-11-07 16:54:31,978 INFO [app:94] usuario 154 carregado com sucesso.
2024-11-07 16:55:02,967 INFO [wasyncore:485] Serving on http://0.0.0.0:8279
2024-11-07 16:55:07,605 INFO [app:94] usuario 154 carregado com sucesso.
2024-11-07 16:55:21,623 INFO [app:94] usuario 154 carregado com sucesso.
2024-11-07 16:55:21,623 INFO [app:195] usuario 154 fez logout.
2024-11-07 16:55:26,418 INFO [app:129] Tentativa de login do usuario: felipe
2024-11-07 16:55:26,776 INFO [app:176] usuario felipe logado com sucesso.
2024-11-07 16:55:26,805 INFO [app:94] usuario 210 carregado com sucesso.
2024-11-07 16:55:28,906 INFO [app:94] usuario 210 carregado com sucesso.
2024-11-07 16:55:37,087 INFO [app:94] usuario 210 carregado com sucesso.
2024-11-07 16:55:37,087 INFO [app:195] usuario 210 fez logout.
2024-11-07 16:55:58,359 INFO [app:129] Tentativa de login do usuario: duin
2024-11-07 16:55:58,765 INFO [app:176] usuario duin logado com sucesso.
2024-11-07 16:55:58,793 INFO [app:94] usuario 192 carregado com sucesso.
2024-11-07 16:56:00,307 INFO [app:94] usuario 192 carregado com sucesso.
2024-11-07 16:58:35,442 INFO [app:94] usuario 192 carregado com sucesso.
2024-11-07 17:09:42,689 INFO [csrf:263] The CSRF session token is missing.
2024-11-07 17:09:42,698 INFO [app:370] Um usuário não autenticado foi deslogado por inatividade
2024-11-07 17:17:46,311 INFO [app:129] Tentativa de login do usuario: Transferência
2024-11-07 17:17:47,036 INFO [app:161] Senha do usuario Transferência atualizada para hash bcrypt.
2024-11-07 17:17:47,374 INFO [app:176] usuario Transferência logado com sucesso.
2024-11-07 17:17:47,412 INFO [app:94] usuario 161 carregado com sucesso.
2024-11-07 17:18:35,992 INFO [app:94] usuario 161 carregado com sucesso.
2024-11-07 17:22:55,611 INFO [wasyncore:485] Serving on http://0.0.0.0:8279
2024-11-07 17:23:01,386 INFO [app:94] usuario 161 carregado com sucesso.
2024-11-07 17:27:54,049 INFO [wasyncore:485] Serving on http://0.0.0.0:8279
2024-11-07 17:27:54,499 INFO [app:94] usuario 161 carregado com sucesso.
2024-11-07 17:27:54,567 ERROR [app:838] Exception on /chamados [GET]
Traceback (most recent call last):
  File "C:\Users\luis.vieira\AppData\Local\Programs\Python\Python312\Lib\site-packages\flask\app.py", line 1473, in wsgi_app
    response = self.full_dispatch_request()
               ^^^^^^^^^^^^^^^^^^^^^^^^^^^^
  File "C:\Users\luis.vieira\AppData\Local\Programs\Python\Python312\Lib\site-packages\flask\app.py", line 883, in full_dispatch_request
    return self.finalize_request(rv)
           ^^^^^^^^^^^^^^^^^^^^^^^^^
  File "C:\Users\luis.vieira\AppData\Local\Programs\Python\Python312\Lib\site-packages\flask\app.py", line 902, in finalize_request
    response = self.make_response(rv)
               ^^^^^^^^^^^^^^^^^^^^^^
  File "C:\Users\luis.vieira\AppData\Local\Programs\Python\Python312\Lib\site-packages\flask\app.py", line 1174, in make_response
    raise TypeError(
TypeError: The view function for 'chamados' did not return a valid response. The function either returned None or ended without a return statement.
2024-11-07 17:27:54,570 ERROR [app:375] Server Error: Traceback (most recent call last):
  File "C:\Users\luis.vieira\AppData\Local\Programs\Python\Python312\Lib\site-packages\flask\app.py", line 1473, in wsgi_app
    response = self.full_dispatch_request()
               ^^^^^^^^^^^^^^^^^^^^^^^^^^^^
  File "C:\Users\luis.vieira\AppData\Local\Programs\Python\Python312\Lib\site-packages\flask\app.py", line 883, in full_dispatch_request
    return self.finalize_request(rv)
           ^^^^^^^^^^^^^^^^^^^^^^^^^
  File "C:\Users\luis.vieira\AppData\Local\Programs\Python\Python312\Lib\site-packages\flask\app.py", line 902, in finalize_request
    response = self.make_response(rv)
               ^^^^^^^^^^^^^^^^^^^^^^
  File "C:\Users\luis.vieira\AppData\Local\Programs\Python\Python312\Lib\site-packages\flask\app.py", line 1174, in make_response
    raise TypeError(
TypeError: The view function for 'chamados' did not return a valid response. The function either returned None or ended without a return statement.

2024-11-07 17:27:56,138 INFO [app:94] usuario 161 carregado com sucesso.
2024-11-07 17:27:56,150 ERROR [app:838] Exception on /chamados [GET]
Traceback (most recent call last):
  File "C:\Users\luis.vieira\AppData\Local\Programs\Python\Python312\Lib\site-packages\flask\app.py", line 1473, in wsgi_app
    response = self.full_dispatch_request()
               ^^^^^^^^^^^^^^^^^^^^^^^^^^^^
  File "C:\Users\luis.vieira\AppData\Local\Programs\Python\Python312\Lib\site-packages\flask\app.py", line 883, in full_dispatch_request
    return self.finalize_request(rv)
           ^^^^^^^^^^^^^^^^^^^^^^^^^
  File "C:\Users\luis.vieira\AppData\Local\Programs\Python\Python312\Lib\site-packages\flask\app.py", line 902, in finalize_request
    response = self.make_response(rv)
               ^^^^^^^^^^^^^^^^^^^^^^
  File "C:\Users\luis.vieira\AppData\Local\Programs\Python\Python312\Lib\site-packages\flask\app.py", line 1174, in make_response
    raise TypeError(
TypeError: The view function for 'chamados' did not return a valid response. The function either returned None or ended without a return statement.
2024-11-07 17:27:56,152 ERROR [app:375] Server Error: Traceback (most recent call last):
  File "C:\Users\luis.vieira\AppData\Local\Programs\Python\Python312\Lib\site-packages\flask\app.py", line 1473, in wsgi_app
    response = self.full_dispatch_request()
               ^^^^^^^^^^^^^^^^^^^^^^^^^^^^
  File "C:\Users\luis.vieira\AppData\Local\Programs\Python\Python312\Lib\site-packages\flask\app.py", line 883, in full_dispatch_request
    return self.finalize_request(rv)
           ^^^^^^^^^^^^^^^^^^^^^^^^^
  File "C:\Users\luis.vieira\AppData\Local\Programs\Python\Python312\Lib\site-packages\flask\app.py", line 902, in finalize_request
    response = self.make_response(rv)
               ^^^^^^^^^^^^^^^^^^^^^^
  File "C:\Users\luis.vieira\AppData\Local\Programs\Python\Python312\Lib\site-packages\flask\app.py", line 1174, in make_response
    raise TypeError(
TypeError: The view function for 'chamados' did not return a valid response. The function either returned None or ended without a return statement.

2024-11-07 17:27:59,555 INFO [app:94] usuario 161 carregado com sucesso.
2024-11-07 17:27:59,783 ERROR [app:838] Exception on /chamados [GET]
Traceback (most recent call last):
  File "C:\Users\luis.vieira\AppData\Local\Programs\Python\Python312\Lib\site-packages\flask\app.py", line 1473, in wsgi_app
    response = self.full_dispatch_request()
               ^^^^^^^^^^^^^^^^^^^^^^^^^^^^
  File "C:\Users\luis.vieira\AppData\Local\Programs\Python\Python312\Lib\site-packages\flask\app.py", line 883, in full_dispatch_request
    return self.finalize_request(rv)
           ^^^^^^^^^^^^^^^^^^^^^^^^^
  File "C:\Users\luis.vieira\AppData\Local\Programs\Python\Python312\Lib\site-packages\flask\app.py", line 902, in finalize_request
    response = self.make_response(rv)
               ^^^^^^^^^^^^^^^^^^^^^^
  File "C:\Users\luis.vieira\AppData\Local\Programs\Python\Python312\Lib\site-packages\flask\app.py", line 1174, in make_response
    raise TypeError(
TypeError: The view function for 'chamados' did not return a valid response. The function either returned None or ended without a return statement.
2024-11-07 17:27:59,785 ERROR [app:375] Server Error: Traceback (most recent call last):
  File "C:\Users\luis.vieira\AppData\Local\Programs\Python\Python312\Lib\site-packages\flask\app.py", line 1473, in wsgi_app
    response = self.full_dispatch_request()
               ^^^^^^^^^^^^^^^^^^^^^^^^^^^^
  File "C:\Users\luis.vieira\AppData\Local\Programs\Python\Python312\Lib\site-packages\flask\app.py", line 883, in full_dispatch_request
    return self.finalize_request(rv)
           ^^^^^^^^^^^^^^^^^^^^^^^^^
  File "C:\Users\luis.vieira\AppData\Local\Programs\Python\Python312\Lib\site-packages\flask\app.py", line 902, in finalize_request
    response = self.make_response(rv)
               ^^^^^^^^^^^^^^^^^^^^^^
  File "C:\Users\luis.vieira\AppData\Local\Programs\Python\Python312\Lib\site-packages\flask\app.py", line 1174, in make_response
    raise TypeError(
TypeError: The view function for 'chamados' did not return a valid response. The function either returned None or ended without a return statement.

2024-11-07 17:28:02,051 INFO [app:94] usuario 161 carregado com sucesso.
2024-11-07 17:28:02,200 ERROR [app:838] Exception on /chamados [GET]
Traceback (most recent call last):
  File "C:\Users\luis.vieira\AppData\Local\Programs\Python\Python312\Lib\site-packages\flask\app.py", line 1473, in wsgi_app
    response = self.full_dispatch_request()
               ^^^^^^^^^^^^^^^^^^^^^^^^^^^^
  File "C:\Users\luis.vieira\AppData\Local\Programs\Python\Python312\Lib\site-packages\flask\app.py", line 883, in full_dispatch_request
    return self.finalize_request(rv)
           ^^^^^^^^^^^^^^^^^^^^^^^^^
  File "C:\Users\luis.vieira\AppData\Local\Programs\Python\Python312\Lib\site-packages\flask\app.py", line 902, in finalize_request
    response = self.make_response(rv)
               ^^^^^^^^^^^^^^^^^^^^^^
  File "C:\Users\luis.vieira\AppData\Local\Programs\Python\Python312\Lib\site-packages\flask\app.py", line 1174, in make_response
    raise TypeError(
TypeError: The view function for 'chamados' did not return a valid response. The function either returned None or ended without a return statement.
2024-11-07 17:28:02,202 ERROR [app:375] Server Error: Traceback (most recent call last):
  File "C:\Users\luis.vieira\AppData\Local\Programs\Python\Python312\Lib\site-packages\flask\app.py", line 1473, in wsgi_app
    response = self.full_dispatch_request()
               ^^^^^^^^^^^^^^^^^^^^^^^^^^^^
  File "C:\Users\luis.vieira\AppData\Local\Programs\Python\Python312\Lib\site-packages\flask\app.py", line 883, in full_dispatch_request
    return self.finalize_request(rv)
           ^^^^^^^^^^^^^^^^^^^^^^^^^
  File "C:\Users\luis.vieira\AppData\Local\Programs\Python\Python312\Lib\site-packages\flask\app.py", line 902, in finalize_request
    response = self.make_response(rv)
               ^^^^^^^^^^^^^^^^^^^^^^
  File "C:\Users\luis.vieira\AppData\Local\Programs\Python\Python312\Lib\site-packages\flask\app.py", line 1174, in make_response
    raise TypeError(
TypeError: The view function for 'chamados' did not return a valid response. The function either returned None or ended without a return statement.

2024-11-07 17:28:06,696 INFO [app:94] usuario 161 carregado com sucesso.
2024-11-07 17:28:10,384 INFO [app:94] usuario 161 carregado com sucesso.
2024-11-07 17:28:13,143 INFO [app:94] usuario 161 carregado com sucesso.
2024-11-07 17:28:14,859 INFO [app:94] usuario 161 carregado com sucesso.
2024-11-07 17:28:14,875 ERROR [app:838] Exception on /chamados [GET]
Traceback (most recent call last):
  File "C:\Users\luis.vieira\AppData\Local\Programs\Python\Python312\Lib\site-packages\flask\app.py", line 1473, in wsgi_app
    response = self.full_dispatch_request()
               ^^^^^^^^^^^^^^^^^^^^^^^^^^^^
  File "C:\Users\luis.vieira\AppData\Local\Programs\Python\Python312\Lib\site-packages\flask\app.py", line 883, in full_dispatch_request
    return self.finalize_request(rv)
           ^^^^^^^^^^^^^^^^^^^^^^^^^
  File "C:\Users\luis.vieira\AppData\Local\Programs\Python\Python312\Lib\site-packages\flask\app.py", line 902, in finalize_request
    response = self.make_response(rv)
               ^^^^^^^^^^^^^^^^^^^^^^
  File "C:\Users\luis.vieira\AppData\Local\Programs\Python\Python312\Lib\site-packages\flask\app.py", line 1174, in make_response
    raise TypeError(
TypeError: The view function for 'chamados' did not return a valid response. The function either returned None or ended without a return statement.
2024-11-07 17:28:14,876 ERROR [app:375] Server Error: Traceback (most recent call last):
  File "C:\Users\luis.vieira\AppData\Local\Programs\Python\Python312\Lib\site-packages\flask\app.py", line 1473, in wsgi_app
    response = self.full_dispatch_request()
               ^^^^^^^^^^^^^^^^^^^^^^^^^^^^
  File "C:\Users\luis.vieira\AppData\Local\Programs\Python\Python312\Lib\site-packages\flask\app.py", line 883, in full_dispatch_request
    return self.finalize_request(rv)
           ^^^^^^^^^^^^^^^^^^^^^^^^^
  File "C:\Users\luis.vieira\AppData\Local\Programs\Python\Python312\Lib\site-packages\flask\app.py", line 902, in finalize_request
    response = self.make_response(rv)
               ^^^^^^^^^^^^^^^^^^^^^^
  File "C:\Users\luis.vieira\AppData\Local\Programs\Python\Python312\Lib\site-packages\flask\app.py", line 1174, in make_response
    raise TypeError(
TypeError: The view function for 'chamados' did not return a valid response. The function either returned None or ended without a return statement.

2024-11-07 17:29:59,820 INFO [wasyncore:485] Serving on http://0.0.0.0:8279
2024-11-07 17:30:01,741 INFO [app:94] usuario 161 carregado com sucesso.
2024-11-07 20:58:42,702 INFO [wasyncore:485] Serving on http://0.0.0.0:8279
2024-11-07 20:59:04,479 WARNING [app:384] Página não encontrada: http://localhost:8279/favicon.ico
2024-11-07 20:59:12,219 INFO [app:129] Tentativa de login do usuario: LUIS
2024-11-07 20:59:13,728 INFO [app:176] usuario LUIS logado com sucesso.
2024-11-07 20:59:13,827 INFO [app:94] usuario 1 carregado com sucesso.
2024-11-07 20:59:20,430 INFO [app:94] usuario 1 carregado com sucesso.
2024-11-07 20:59:44,506 INFO [app:94] usuario 1 carregado com sucesso.
2024-11-07 20:59:46,768 INFO [app:94] usuario 1 carregado com sucesso.
2024-11-07 20:59:59,288 INFO [app:94] usuario 1 carregado com sucesso.
2024-11-07 21:00:01,477 INFO [app:94] usuario 1 carregado com sucesso.
2024-11-07 21:02:14,928 INFO [wasyncore:485] Serving on http://0.0.0.0:8279
2024-11-07 21:02:20,602 INFO [app:94] usuario 1 carregado com sucesso.
2024-11-07 21:07:17,003 INFO [wasyncore:485] Serving on http://0.0.0.0:8279
2024-11-07 21:07:22,717 INFO [app:94] usuario 1 carregado com sucesso.
2024-11-07 21:07:34,205 INFO [app:94] usuario 1 carregado com sucesso.
2024-11-07 21:07:35,187 WARNING [app:383] Página não encontrada: http://localhost:8279/favicon.ico
2024-11-07 21:07:35,343 INFO [app:94] usuario 1 carregado com sucesso.
2024-11-07 21:09:50,304 INFO [wasyncore:485] Serving on http://0.0.0.0:8279
2024-11-07 21:09:56,186 INFO [app:94] usuario 1 carregado com sucesso.
2024-11-07 21:10:02,188 INFO [app:94] usuario 1 carregado com sucesso.
2024-11-07 21:10:06,871 INFO [app:94] usuario 1 carregado com sucesso.
2024-11-07 21:10:07,859 WARNING [app:383] Página não encontrada: http://localhost:8279/favicon.ico
2024-11-07 21:10:08,040 INFO [app:94] usuario 1 carregado com sucesso.
2024-11-07 21:10:47,948 INFO [app:94] usuario 1 carregado com sucesso.
2024-11-07 21:10:47,948 INFO [app:195] usuario 1 fez logout.
2024-11-07 21:11:10,878 INFO [app:129] Tentativa de login do usuario: luis
2024-11-07 21:11:11,820 INFO [app:176] usuario luis logado com sucesso.
2024-11-07 21:11:11,916 INFO [app:94] usuario 1 carregado com sucesso.
2024-11-07 21:11:13,479 INFO [app:94] usuario 1 carregado com sucesso.
2024-11-07 21:11:52,569 INFO [wasyncore:485] Serving on http://0.0.0.0:8279
2024-11-07 21:11:58,055 INFO [app:94] usuario 1 carregado com sucesso.
2024-11-07 21:18:39,336 INFO [app:94] usuario 1 carregado com sucesso.
2024-11-07 21:22:14,858 INFO [app:94] usuario 1 carregado com sucesso.
2024-11-07 21:22:38,399 INFO [wasyncore:485] Serving on http://0.0.0.0:8279
2024-11-07 21:22:46,339 INFO [app:94] usuario 1 carregado com sucesso.
2024-11-07 21:24:02,060 INFO [app:94] usuario 1 carregado com sucesso.
2024-11-07 21:26:22,728 INFO [app:94] usuario 1 carregado com sucesso.
2024-11-07 21:27:23,452 INFO [app:94] usuario 1 carregado com sucesso.
2024-11-07 21:27:24,488 WARNING [app:383] Página não encontrada: http://localhost:8279/favicon.ico
2024-11-07 21:27:24,560 INFO [app:94] usuario 1 carregado com sucesso.
2024-11-07 21:39:11,348 INFO [csrf:263] The CSRF session token is missing.
2024-11-07 21:39:11,350 INFO [app:370] Um usuário não autenticado foi deslogado por inatividade
2024-11-07 21:39:19,840 INFO [app:129] Tentativa de login do usuario: luis
2024-11-07 21:39:20,684 INFO [app:176] usuario luis logado com sucesso.
2024-11-07 21:39:20,792 INFO [app:94] usuario 1 carregado com sucesso.
2024-11-07 21:39:22,666 INFO [app:94] usuario 1 carregado com sucesso.
2024-11-07 21:40:18,261 INFO [wasyncore:485] Serving on http://0.0.0.0:8279
2024-11-07 21:40:23,207 INFO [app:94] usuario 1 carregado com sucesso.
2024-11-07 21:44:33,174 INFO [wasyncore:485] Serving on http://0.0.0.0:8279
2024-11-07 21:44:39,648 INFO [app:94] usuario 1 carregado com sucesso.
2024-11-07 21:44:49,134 INFO [wasyncore:485] Serving on http://0.0.0.0:8279
2024-11-07 21:44:55,462 INFO [app:94] usuario 1 carregado com sucesso.
2024-11-07 21:44:56,683 INFO [app:94] usuario 1 carregado com sucesso.
2024-11-07 21:45:35,055 INFO [wasyncore:485] Serving on http://0.0.0.0:8279
2024-11-07 21:45:37,502 INFO [app:94] usuario 1 carregado com sucesso.
2024-11-07 21:45:41,745 INFO [app:94] usuario 1 carregado com sucesso.
2024-11-07 21:46:55,519 INFO [app:94] usuario 1 carregado com sucesso.
2024-11-07 21:48:01,228 INFO [wasyncore:485] Serving on http://0.0.0.0:8279
2024-11-07 21:48:09,715 INFO [app:94] usuario 1 carregado com sucesso.
2024-11-07 21:48:20,375 INFO [app:94] usuario 1 carregado com sucesso.
2024-11-07 21:48:24,094 WARNING [task:114] Task queue depth is 1
2024-11-07 21:48:24,095 WARNING [task:114] Task queue depth is 2
2024-11-07 21:48:30,885 INFO [app:94] usuario 1 carregado com sucesso.
2024-11-07 21:48:58,023 INFO [app:94] usuario 1 carregado com sucesso.
2024-11-07 21:48:59,661 INFO [app:94] usuario 1 carregado com sucesso.
2024-11-07 21:53:06,385 INFO [wasyncore:485] Serving on http://0.0.0.0:8279
2024-11-07 21:53:10,964 INFO [app:94] usuario 1 carregado com sucesso.
2024-11-07 21:56:37,218 INFO [wasyncore:485] Serving on http://0.0.0.0:8279
2024-11-07 21:56:41,187 INFO [app:94] usuario 1 carregado com sucesso.
2024-11-07 21:58:09,826 INFO [wasyncore:485] Serving on http://0.0.0.0:8279
2024-11-07 21:58:13,932 INFO [app:94] usuario 1 carregado com sucesso.
2024-11-07 22:05:05,217 INFO [wasyncore:485] Serving on http://0.0.0.0:8279
2024-11-07 22:05:12,524 INFO [app:94] usuario 1 carregado com sucesso.
2024-11-07 22:05:14,424 WARNING [app:383] Página não encontrada: http://localhost:8279/site.webmanifest
2024-11-07 22:05:14,426 WARNING [app:383] Página não encontrada: http://localhost:8279/favicon-32x32.png
2024-11-07 22:05:14,515 INFO [app:94] usuario 1 carregado com sucesso.
2024-11-07 22:05:14,531 WARNING [app:383] Página não encontrada: http://localhost:8279/favicon-16x16.png
2024-11-07 22:05:14,608 INFO [app:94] usuario 1 carregado com sucesso.
2024-11-07 22:06:07,010 INFO [wasyncore:485] Serving on http://0.0.0.0:8279
2024-11-07 22:06:10,480 INFO [app:94] usuario 1 carregado com sucesso.
2024-11-07 22:06:12,371 WARNING [app:383] Página não encontrada: http://localhost:8279/.../favicon-32x32.png
2024-11-07 22:06:12,417 WARNING [app:383] Página não encontrada: http://localhost:8279/.../site.webmanifest
2024-11-07 22:06:12,454 INFO [app:94] usuario 1 carregado com sucesso.
2024-11-07 22:06:12,470 WARNING [app:383] Página não encontrada: http://localhost:8279/.../favicon-16x16.png
2024-11-07 22:06:12,552 INFO [app:94] usuario 1 carregado com sucesso.
2024-11-07 22:08:51,303 INFO [wasyncore:485] Serving on http://0.0.0.0:8279
2024-11-07 22:08:55,665 INFO [app:94] usuario 1 carregado com sucesso.
2024-11-07 22:09:53,824 INFO [app:94] usuario 1 carregado com sucesso.
2024-11-07 22:10:31,380 INFO [app:94] usuario 1 carregado com sucesso.
2024-11-07 22:10:32,907 INFO [app:94] usuario 1 carregado com sucesso.
2024-11-07 22:19:56,671 INFO [wasyncore:485] Serving on http://0.0.0.0:8279
2024-11-07 22:20:12,250 WARNING [app:383] Página não encontrada: http://localhost:8279/android-chrome-192x192.png
2024-11-07 22:20:12,250 WARNING [app:383] Página não encontrada: http://localhost:8279/android-chrome-512x512.png
2024-11-07 22:20:19,978 INFO [app:129] Tentativa de login do usuario: luis
2024-11-07 22:20:20,474 INFO [app:176] usuario luis logado com sucesso.
2024-11-07 22:20:20,559 INFO [app:94] usuario 1 carregado com sucesso.
2024-11-07 22:20:22,709 INFO [app:94] usuario 1 carregado com sucesso.
2024-11-07 22:22:57,541 INFO [app:94] usuario 1 carregado com sucesso.
2024-11-07 22:22:57,541 INFO [app:195] usuario 1 fez logout.
2024-11-07 23:07:24,146 INFO [wasyncore:485] Serving on http://0.0.0.0:8279
2024-11-07 23:07:27,181 WARNING [app:383] Página não encontrada: http://localhost:8279/android-chrome-192x192.png
2024-11-07 23:07:27,200 WARNING [app:383] Página não encontrada: http://localhost:8279/android-chrome-512x512.png
2024-11-07 23:10:54,091 INFO [wasyncore:485] Serving on http://0.0.0.0:8279
2024-11-07 23:14:31,755 INFO [wasyncore:485] Serving on http://0.0.0.0:8279
2024-11-07 23:15:51,420 INFO [wasyncore:485] Serving on http://0.0.0.0:8279
2024-11-07 23:16:08,304 INFO [app:129] Tentativa de login do usuario: luis
2024-11-07 23:16:08,779 INFO [app:176] usuario luis logado com sucesso.
2024-11-07 23:16:08,860 INFO [app:94] usuario 1 carregado com sucesso.
2024-11-07 23:16:13,944 INFO [app:94] usuario 1 carregado com sucesso.
2024-11-07 23:20:35,664 INFO [wasyncore:485] Serving on http://0.0.0.0:8279
2024-11-07 23:20:50,085 INFO [app:94] usuario 1 carregado com sucesso.
2024-11-07 23:21:07,564 INFO [app:94] usuario 1 carregado com sucesso.
2024-11-07 23:21:16,727 INFO [app:94] usuario 1 carregado com sucesso.
